Workbook

Sheet Instructions
A1: Instructions:
A3: 1. Pick one of the orange tabs that has not been filled in already
A4: 2. Follow the instructions on that orange tab
A5: 3. Once all team members have filled their respective orange tabs, check the 'Team Availablity' tab
A6: and change the time zone value in that 'Team Availability' tab to your time zone to see team availability in your time zone

Sheet Jenny Li
A1: Step 1: Rename the sheet name with your name, for example 'Member 1 Name' to 'Your Name' | J1: Time Zone
A2: Step 2: Choose your time zone from yellow drop down box | J2: CST
A3: Step 3: Enter '1' in all 30-minute slots you're NOT available in orange area | J3: {=_xlfn.SWITCH(J2,"PST",0,"MST",1,"CST",2,"EST",3,0)} -> 2
A6: Time | B6: Monday | C6: Tuesday | D6: Wednesday | E6: Thursday | F6: Friday | G6: Saturday | H6: Sunday
A7: =TEXT(TIME(3,0,0)+$J$3/24,"h:mm AM/PM") & " - " & TEXT(TIME(3,30,0)+$J$3/24,"h:mm AM/PM") -> 5:00 AM - 5:30 AM | B7: 1 | C7: 1 | D7: 1 | E7: 1 | F7: 1 | G7: 1 | H7: 1
A8: =TEXT(TIMEVALUE(LEFT(A7,FIND(" -",A7)-1))+TIME(0,30,0), "h:mm AM/PM") & " - " & TEXT(TIMEVALUE(MID(A7,FIND("- ",A7)+2,99))+TIME(0,30,0), "h:mm AM/PM") -> 5:30 AM - 6:00 AM | B8: 1 | C8: 1 | D8: 1 | E8: 1 | F8: 1 | G8: 1 | H8: 1
A9: =TEXT(TIMEVALUE(LEFT(A8,FIND(" -",A8)-1))+TIME(0,30,0), "h:mm AM/PM") & " - " & TEXT(TIMEVALUE(MID(A8,FIND("- ",A8)+2,99))+TIME(0,30,0), "h:mm AM/PM") -> 6:00 AM - 6:30 AM | B9: 1 | C9: 1 | D9: 1 | E9: 1 | F9: 1 | G9: 1 | H9: 1
A10: =TEXT(TIMEVALUE(LEFT(A9,FIND(" -",A9)-1))+TIME(0,30,0), "h:mm AM/PM") & " - " & TEXT(TIMEVALUE(MID(A9,FIND("- ",A9)+2,99))+TIME(0,30,0), "h:mm AM/PM") -> 6:30 AM - 7:00 AM | B10: 1 | C10: 1 | D10: 1 | E10: 1 | F10: 1 | G10: 1 | H10: 1
A11: =TEXT(TIMEVALUE(LEFT(A10,FIND(" -",A10)-1))+TIME(0,30,0), "h:mm AM/PM") & " - " & TEXT(TIMEVALUE(MID(A10,FIND("- ",A10)+2,99))+TIME(0,30,0), "h:mm AM/PM") -> 7:00 AM - 7:30 AM | B11: 1 | C11: 1 | D11: 1 | E11: 1 | F11: 1 | G11: 1 | H11: 1
A12: =TEXT(TIMEVALUE(LEFT(A11,FIND(" -",A11)-1))+TIME(0,30,0), "h:mm AM/PM") & " - " & TEXT(TIMEVALUE(MID(A11,FIND("- ",A11)+2,99))+TIME(0,30,0), "h:mm AM/PM") -> 7:30 AM - 8:00 AM | B12: 1 | C12: 1 | D12: 1 | E12: 1 | F12: 1 | G12: 1 | H12: 1
A13: =TEXT(TIMEVALUE(LEFT(A12,FIND(" -",A12)-1))+TIME(0,30,0), "h:mm AM/PM") & " - " & TEXT(TIMEVALUE(MID(A12,FIND("- ",A12)+2,99))+TIME(0,30,0), "h:mm AM/PM") -> 8:00 AM - 8:30 AM | B13: 1 | C13: 1 | D13: 1 | E13: 1 | F13: 1 | G13: 1 | H13: 1
A14: =TEXT(TIMEVALUE(LEFT(A13,FIND(" -",A13)-1))+TIME(0,30,0), "h:mm AM/PM") & " - " & TEXT(TIMEVALUE(MID(A13,FIND("- ",A13)+2,99))+TIME(0,30,0), "h:mm AM/PM") -> 8:30 AM - 9:00 AM | B14: 1 | C14: 1 | D14: 1 | E14: 1 | F14: 1 | G14: 1 | H14: 1
A15: =TEXT(TIMEVALUE(LEFT(A14,FIND(" -",A14)-1))+TIME(0,30,0), "h:mm AM/PM") & " - " & TEXT(TIMEVALUE(MID(A14,FIND("- ",A14)+2,99))+TIME(0,30,0), "h:mm AM/PM") -> 9:00 AM - 9:30 AM | B15: 1 | C15: 1 | D15: 1 | E15: 1 | F15: 1 | G15: 1 | H15: 1
A16: =TEXT(TIMEVALUE(LEFT(A15,FIND(" -",A15)-1))+TIME(0,30,0), "h:mm AM/PM") & " - " & TEXT(TIMEVALUE(MID(A15,FIND("- ",A15)+2,99))+TIME(0,30,0), "h:mm AM/PM") -> 9:30 AM - 10:00 AM | B16: 1 | C16: 1 | D16: 1 | E16: 1 | F16: 1 | G16: 1 | H16: 1
A17: =TEXT(TIMEVALUE(LEFT(A16,FIND(" -",A16)-1))+TIME(0,30,0), "h:mm AM/PM") & " - " & TEXT(TIMEVALUE(MID(A16,FIND("- ",A16)+2,99))+TIME(0,30,0), "h:mm AM/PM") -> 10:00 AM - 10:30 AM | B17: 1 | C17: 1 | D17: 1 | E17: 1 | F17: 1 | G17: 1 | H17: 1
A18: =TEXT(TIMEVALUE(LEFT(A17,FIND(" -",A17)-1))+TIME(0,30,0), "h:mm AM/PM") & " - " & TEXT(TIMEVALUE(MID(A17,FIND("- ",A17)+2,99))+TIME(0,30,0), "h:mm AM/PM") -> 10:30 AM - 11:00 AM | B18: 1 | C18: 1 | D18: 1 | E18: 1 | F18: 1 | G18: 1 | H18: 1
A19: =TEXT(TIMEVALUE(LEFT(A18,FIND(" -",A18)-1))+TIME(0,30,0), "h:mm AM/PM") & " - " & TEXT(TIMEVALUE(MID(A18,FIND("- ",A18)+2,99))+TIME(0,30,0), "h:mm AM/PM") -> 11:00 AM - 11:30 AM | B19: 1 | D19: 1 | F19: 1 | G19: 1
A20: =TEXT(TIMEVALUE(LEFT(A19,FIND(" -",A19)-1))+TIME(0,30,0), "h:mm AM/PM") & " - " & TEXT(TIMEVALUE(MID(A19,FIND("- ",A19)+2,99))+TIME(0,30,0), "h:mm AM/PM") -> 11:30 AM - 12:00 PM | B20: 1 | D20: 1 | F20: 1 | G20: 1
A21: =TEXT(TIMEVALUE(LEFT(A20,FIND(" -",A20)-1))+TIME(0,30,0), "h:mm AM/PM") & " - " & TEXT(TIMEVALUE(MID(A20,FIND("- ",A20)+2,99))+TIME(0,30,0), "h:mm AM/PM") -> 12:00 PM - 12:30 PM | B21: 1 | D21: 1 | F21: 1 | G21: 1
A22: =TEXT(TIMEVALUE(LEFT(A21,FIND(" -",A21)-1))+TIME(0,30,0), "h:mm AM/PM") & " - " & TEXT(TIMEVALUE(MID(A21,FIND("- ",A21)+2,99))+TIME(0,30,0), "h:mm AM/PM") -> 12:30 PM - 1:00 PM | B22: 1 | D22: 1 | F22: 1 | G22: 1
A23: =TEXT(TIMEVALUE(LEFT(A22,FIND(" -",A22)-1))+TIME(0,30,0), "h:mm AM/PM") & " - " & TEXT(TIMEVALUE(MID(A22,FIND("- ",A22)+2,99))+TIME(0,30,0), "h:mm AM/PM") -> 1:00 PM - 1:30 PM | B23: 1 | D23: 1 | F23: 1 | G23: 1
A24: =TEXT(TIMEVALUE(LEFT(A23,FIND(" -",A23)-1))+TIME(0,30,0), "h:mm AM/PM") & " - " & TEXT(TIMEVALUE(MID(A23,FIND("- ",A23)+2,99))+TIME(0,30,0), "h:mm AM/PM") -> 1:30 PM - 2:00 PM | B24: 1 | D24: 1 | F24: 1 | G24: 1
A25: =TEXT(TIMEVALUE(LEFT(A24,FIND(" -",A24)-1))+TIME(0,30,0), "h:mm AM/PM") & " - " & TEXT(TIMEVALUE(MID(A24,FIND("- ",A24)+2,99))+TIME(0,30,0), "h:mm AM/PM") -> 2:00 PM - 2:30 PM | B25: 1 | D25: 1 | G25: 1
A26: =TEXT(TIMEVALUE(LEFT(A25,FIND(" -",A25)-1))+TIME(0,30,0), "h:mm AM/PM") & " - " & TEXT(TIMEVALUE(MID(A25,FIND("- ",A25)+2,99))+TIME(0,30,0), "h:mm AM/PM") -> 2:30 PM - 3:00 PM | B26: 1 | D26: 1 | G26: 1
A27: =TEXT(TIMEVALUE(LEFT(A26,FIND(" -",A26)-1))+TIME(0,30,0), "h:mm AM/PM") & " - " & TEXT(TIMEVALUE(MID(A26,FIND("- ",A26)+2,99))+TIME(0,30,0), "h:mm AM/PM") -> 3:00 PM - 3:30 PM | B27: 1 | D27: 1
A28: =TEXT(TIMEVALUE(LEFT(A27,FIND(" -",A27)-1))+TIME(0,30,0), "h:mm AM/PM") & " - " & TEXT(TIMEVALUE(MID(A27,FIND("- ",A27)+2,99))+TIME(0,30,0), "h:mm AM/PM") -> 3:30 PM - 4:00 PM | B28: 1 | D28: 1
A29: =TEXT(TIMEVALUE(LEFT(A28,FIND(" -",A28)-1))+TIME(0,30,0), "h:mm AM/PM") & " - " & TEXT(TIMEVALUE(MID(A28,FIND("- ",A28)+2,99))+TIME(0,30,0), "h:mm AM/PM") -> 4:00 PM - 4:30 PM | B29: 1 | D29: 1
A30: =TEXT(TIMEVALUE(LEFT(A29,FIND(" -",A29)-1))+TIME(0,30,0), "h:mm AM/PM") & " - " & TEXT(TIMEVALUE(MID(A29,FIND("- ",A29)+2,99))+TIME(0,30,0), "h:mm AM/PM") -> 4:30 PM - 5:00 PM | B30: 1 | D30: 1
A31: =TEXT(TIMEVALUE(LEFT(A30,FIND(" -",A30)-1))+TIME(0,30,0), "h:mm AM/PM") & " - " & TEXT(TIMEVALUE(MID(A30,FIND("- ",A30)+2,99))+TIME(0,30,0), "h:mm AM/PM") -> 5:00 PM - 5:30 PM | B31: 1 | D31: 1
A32: =TEXT(TIMEVALUE(LEFT(A31,FIND(" -",A31)-1))+TIME(0,30,0), "h:mm AM/PM") & " - " & TEXT(TIMEVALUE(MID(A31,FIND("- ",A31)+2,99))+TIME(0,30,0), "h:mm AM/PM") -> 5:30 PM - 6:00 PM | B32: 1 | D32: 1
A33: =TEXT(TIMEVALUE(LEFT(A32,FIND(" -",A32)-1))+TIME(0,30,0), "h:mm AM/PM") & " - " & TEXT(TIMEVALUE(MID(A32,FIND("- ",A32)+2,99))+TIME(0,30,0), "h:mm AM/PM") -> 6:00 PM - 6:30 PM | B33: 1 | D33: 1
A34: =TEXT(TIMEVALUE(LEFT(A33,FIND(" -",A33)-1))+TIME(0,30,0), "h:mm AM/PM") & " - " & TEXT(TIMEVALUE(MID(A33,FIND("- ",A33)+2,99))+TIME(0,30,0), "h:mm AM/PM") -> 6:30 PM - 7:00 PM | B34: 1 | D34: 1
A35: =TEXT(TIMEVALUE(LEFT(A34,FIND(" -",A34)-1))+TIME(0,30,0), "h:mm AM/PM") & " - " & TEXT(TIMEVALUE(MID(A34,FIND("- ",A34)+2,99))+TIME(0,30,0), "h:mm AM/PM") -> 7:00 PM - 7:30 PM | B35: 1 | D35: 1
A36: =TEXT(TIMEVALUE(LEFT(A35,FIND(" -",A35)-1))+TIME(0,30,0), "h:mm AM/PM") & " - " & TEXT(TIMEVALUE(MID(A35,FIND("- ",A35)+2,99))+TIME(0,30,0), "h:mm AM/PM") -> 7:30 PM - 8:00 PM | B36: 1 | D36: 1
A37: =TEXT(TIMEVALUE(LEFT(A36,FIND(" -",A36)-1))+TIME(0,30,0), "h:mm AM/PM") & " - " & TEXT(TIMEVALUE(MID(A36,FIND("- ",A36)+2,99))+TIME(0,30,0), "h:mm AM/PM") -> 8:00 PM - 8:30 PM
A38: =TEXT(TIMEVALUE(LEFT(A37,FIND(" -",A37)-1))+TIME(0,30,0), "h:mm AM/PM") & " - " & TEXT(TIMEVALUE(MID(A37,FIND("- ",A37)+2,99))+TIME(0,30,0), "h:mm AM/PM") -> 8:30 PM - 9:00 PM
A39: =TEXT(TIMEVALUE(LEFT(A38,FIND(" -",A38)-1))+TIME(0,30,0), "h:mm AM/PM") & " - " & TEXT(TIMEVALUE(MID(A38,FIND("- ",A38)+2,99))+TIME(0,30,0), "h:mm AM/PM") -> 9:00 PM - 9:30 PM
A40: =TEXT(TIMEVALUE(LEFT(A39,FIND(" -",A39)-1))+TIME(0,30,0), "h:mm AM/PM") & " - " & TEXT(TIMEVALUE(MID(A39,FIND("- ",A39)+2,99))+TIME(0,30,0), "h:mm AM/PM") -> 9:30 PM - 10:00 PM
A41: =TEXT(TIMEVALUE(LEFT(A40,FIND(" -",A40)-1))+TIME(0,30,0), "h:mm AM/PM") & " - " & TEXT(TIMEVALUE(MID(A40,FIND("- ",A40)+2,99))+TIME(0,30,0), "h:mm AM/PM") -> 10:00 PM - 10:30 PM
A42: =TEXT(TIMEVALUE(LEFT(A41,FIND(" -",A41)-1))+TIME(0,30,0), "h:mm AM/PM") & " - " & TEXT(TIMEVALUE(MID(A41,FIND("- ",A41)+2,99))+TIME(0,30,0), "h:mm AM/PM") -> 10:30 PM - 11:00 PM
...

Sheet Huiyu Yie
A1: Step 1: Rename the sheet name with your name, for example 'Member 2 Name' to 'Your Name' | J1: Time Zone
A2: Step 2: Choose your time zone from yellow drop down box | J2: PST
A3: Step 3: Enter '1' in all 30-minute slots you're NOT available in orange area | J3: {=_xlfn.SWITCH(J2,"PST",0,"MST",1,"CST",2,"EST",3,0)} -> 0
A6: Time | B6: Monday | C6: Tuesday | D6: Wednesday | E6: Thursday | F6: Friday | G6: Saturday | H6: Sunday
A7: =TEXT(TIME(3,0,0)+$J$3/24,"h:mm AM/PM") & " - " & TEXT(TIME(3,30,0)+$J$3/24,"h:mm AM/PM") -> 3:00 AM - 3:30 AM | B7: 1 | C7: 1 | D7: 1 | E7: 1 | F7: 1 | G7: 1 | H7: 1
A8: =TEXT(TIMEVALUE(LEFT(A7,FIND(" -",A7)-1))+TIME(0,30,0), "h:mm AM/PM") & " - " & TEXT(TIMEVALUE(MID(A7,FIND("- ",A7)+2,99))+TIME(0,30,0), "h:mm AM/PM") -> 3:30 AM - 4:00 AM | B8: 1 | C8: 1 | D8: 1 | E8: 1 | F8: 1 | G8: 1 | H8: 1
A9: =TEXT(TIMEVALUE(LEFT(A8,FIND(" -",A8)-1))+TIME(0,30,0), "h:mm AM/PM") & " - " & TEXT(TIMEVALUE(MID(A8,FIND("- ",A8)+2,99))+TIME(0,30,0), "h:mm AM/PM") -> 4:00 AM - 4:30 AM | B9: 1 | C9: 1 | D9: 1 | E9: 1 | F9: 1 | G9: 1 | H9: 1
A10: =TEXT(TIMEVALUE(LEFT(A9,FIND(" -",A9)-1))+TIME(0,30,0), "h:mm AM/PM") & " - " & TEXT(TIMEVALUE(MID(A9,FIND("- ",A9)+2,99))+TIME(0,30,0), "h:mm AM/PM") -> 4:30 AM - 5:00 AM | B10: 1 | C10: 1 | D10: 1 | E10: 1 | F10: 1 | G10: 1 | H10: 1
A11: =TEXT(TIMEVALUE(LEFT(A10,FIND(" -",A10)-1))+TIME(0,30,0), "h:mm AM/PM") & " - " & TEXT(TIMEVALUE(MID(A10,FIND("- ",A10)+2,99))+TIME(0,30,0), "h:mm AM/PM") -> 5:00 AM - 5:30 AM | B11: 1 | C11: 1 | D11: 1 | E11: 1 | F11: 1 | G11: 1 | H11: 1
A12: =TEXT(TIMEVALUE(LEFT(A11,FIND(" -",A11)-1))+TIME(0,30,0), "h:mm AM/PM") & " - " & TEXT(TIMEVALUE(MID(A11,FIND("- ",A11)+2,99))+TIME(0,30,0), "h:mm AM/PM") -> 5:30 AM - 6:00 AM | B12: 1 | C12: 1 | D12: 1 | E12: 1 | F12: 1 | G12: 1 | H12: 1
A13: =TEXT(TIMEVALUE(LEFT(A12,FIND(" -",A12)-1))+TIME(0,30,0), "h:mm AM/PM") & " - " & TEXT(TIMEVALUE(MID(A12,FIND("- ",A12)+2,99))+TIME(0,30,0), "h:mm AM/PM") -> 6:00 AM - 6:30 AM | B13: 1 | C13: 1 | D13: 1 | E13: 1 | F13: 1 | G13: 1 | H13: 1
A14: =TEXT(TIMEVALUE(LEFT(A13,FIND(" -",A13)-1))+TIME(0,30,0), "h:mm AM/PM") & " - " & TEXT(TIMEVALUE(MID(A13,FIND("- ",A13)+2,99))+TIME(0,30,0), "h:mm AM/PM") -> 6:30 AM - 7:00 AM | B14: 1 | C14: 1 | D14: 1 | E14: 1 | F14: 1 | G14: 1 | H14: 1
A15: =TEXT(TIMEVALUE(LEFT(A14,FIND(" -",A14)-1))+TIME(0,30,0), "h:mm AM/PM") & " - " & TEXT(TIMEVALUE(MID(A14,FIND("- ",A14)+2,99))+TIME(0,30,0), "h:mm AM/PM") -> 7:00 AM - 7:30 AM | B15: 1 | C15: 1 | D15: 1 | E15: 1 | F15: 1 | G15: 1 | H15: 1
A16: =TEXT(TIMEVALUE(LEFT(A15,FIND(" -",A15)-1))+TIME(0,30,0), "h:mm AM/PM") & " - " & TEXT(TIMEVALUE(MID(A15,FIND("- ",A15)+2,99))+TIME(0,30,0), "h:mm AM/PM") -> 7:30 AM - 8:00 AM | B16: 1 | C16: 1 | D16: 1 | E16: 1 | F16: 1 | G16: 1 | H16: 1
A17: =TEXT(TIMEVALUE(LEFT(A16,FIND(" -",A16)-1))+TIME(0,30,0), "h:mm AM/PM") & " - " & TEXT(TIMEVALUE(MID(A16,FIND("- ",A16)+2,99))+TIME(0,30,0), "h:mm AM/PM") -> 8:00 AM - 8:30 AM | B17: 1 | C17: 1 | D17: 1 | E17: 1 | F17: 1 | G17: 1 | H17: 1
A18: =TEXT(TIMEVALUE(LEFT(A17,FIND(" -",A17)-1))+TIME(0,30,0), "h:mm AM/PM") & " - " & TEXT(TIMEVALUE(MID(A17,FIND("- ",A17)+2,99))+TIME(0,30,0), "h:mm AM/PM") -> 8:30 AM - 9:00 AM | B18: 1 | C18: 1 | D18: 1 | E18: 1 | F18: 1 | G18: 1 | H18: 1
A19: =TEXT(TIMEVALUE(LEFT(A18,FIND(" -",A18)-1))+TIME(0,30,0), "h:mm AM/PM") & " - " & TEXT(TIMEVALUE(MID(A18,FIND("- ",A18)+2,99))+TIME(0,30,0), "h:mm AM/PM") -> 9:00 AM - 9:30 AM | B19: 1 | C19: 1 | D19: 1 | E19: 1 | F19: 1
A20: =TEXT(TIMEVALUE(LEFT(A19,FIND(" -",A19)-1))+TIME(0,30,0), "h:mm AM/PM") & " - " & TEXT(TIMEVALUE(MID(A19,FIND("- ",A19)+2,99))+TIME(0,30,0), "h:mm AM/PM") -> 9:30 AM - 10:00 AM | B20: 1 | C20: 1 | D20: 1 | E20: 1 | F20: 1
A21: =TEXT(TIMEVALUE(LEFT(A20,FIND(" -",A20)-1))+TIME(0,30,0), "h:mm AM/PM") & " - " & TEXT(TIMEVALUE(MID(A20,FIND("- ",A20)+2,99))+TIME(0,30,0), "h:mm AM/PM") -> 10:00 AM - 10:30 AM | B21: 1 | C21: 1 | D21: 1 | E21: 1 | F21: 1
A22: =TEXT(TIMEVALUE(LEFT(A21,FIND(" -",A21)-1))+TIME(0,30,0), "h:mm AM/PM") & " - " & TEXT(TIMEVALUE(MID(A21,FIND("- ",A21)+2,99))+TIME(0,30,0), "h:mm AM/PM") -> 10:30 AM - 11:00 AM | B22: 1 | C22: 1 | D22: 1 | E22: 1 | F22: 1
A23: =TEXT(TIMEVALUE(LEFT(A22,FIND(" -",A22)-1))+TIME(0,30,0), "h:mm AM/PM") & " - " & TEXT(TIMEVALUE(MID(A22,FIND("- ",A22)+2,99))+TIME(0,30,0), "h:mm AM/PM") -> 11:00 AM - 11:30 AM | B23: 1 | C23: 1 | D23: 1 | E23: 1 | F23: 1
A24: =TEXT(TIMEVALUE(LEFT(A23,FIND(" -",A23)-1))+TIME(0,30,0), "h:mm AM/PM") & " - " & TEXT(TIMEVALUE(MID(A23,FIND("- ",A23)+2,99))+TIME(0,30,0), "h:mm AM/PM") -> 11:30 AM - 12:00 PM | B24: 1 | C24: 1 | D24: 1 | E24: 1 | F24: 1
A25: =TEXT(TIMEVALUE(LEFT(A24,FIND(" -",A24)-1))+TIME(0,30,0), "h:mm AM/PM") & " - " & TEXT(TIMEVALUE(MID(A24,FIND("- ",A24)+2,99))+TIME(0,30,0), "h:mm AM/PM") -> 12:00 PM - 12:30 PM | B25: 1 | C25: 1 | D25: 1 | E25: 1 | F25: 1
A26: =TEXT(TIMEVALUE(LEFT(A25,FIND(" -",A25)-1))+TIME(0,30,0), "h:mm AM/PM") & " - " & TEXT(TIMEVALUE(MID(A25,FIND("- ",A25)+2,99))+TIME(0,30,0), "h:mm AM/PM") -> 12:30 PM - 1:00 PM | B26: 1 | C26: 1 | D26: 1 | E26: 1 | F26: 1
A27: =TEXT(TIMEVALUE(LEFT(A26,FIND(" -",A26)-1))+TIME(0,30,0), "h:mm AM/PM") & " - " & TEXT(TIMEVALUE(MID(A26,FIND("- ",A26)+2,99))+TIME(0,30,0), "h:mm AM/PM") -> 1:00 PM - 1:30 PM | B27: 1 | C27: 1 | D27: 1 | E27: 1 | F27: 1
A28: =TEXT(TIMEVALUE(LEFT(A27,FIND(" -",A27)-1))+TIME(0,30,0), "h:mm AM/PM") & " - " & TEXT(TIMEVALUE(MID(A27,FIND("- ",A27)+2,99))+TIME(0,30,0), "h:mm AM/PM") -> 1:30 PM - 2:00 PM | B28: 1 | C28: 1 | D28: 1 | E28: 1 | F28: 1
A29: =TEXT(TIMEVALUE(LEFT(A28,FIND(" -",A28)-1))+TIME(0,30,0), "h:mm AM/PM") & " - " & TEXT(TIMEVALUE(MID(A28,FIND("- ",A28)+2,99))+TIME(0,30,0), "h:mm AM/PM") -> 2:00 PM - 2:30 PM | B29: 1 | C29: 1 | D29: 1 | E29: 1 | F29: 1
A30: =TEXT(TIMEVALUE(LEFT(A29,FIND(" -",A29)-1))+TIME(0,30,0), "h:mm AM/PM") & " - " & TEXT(TIMEVALUE(MID(A29,FIND("- ",A29)+2,99))+TIME(0,30,0), "h:mm AM/PM") -> 2:30 PM - 3:00 PM | B30: 1 | C30: 1 | D30: 1 | E30: 1 | F30: 1
... A40: =TEXT(TIMEVALUE(LEFT(A39,FIND(" -",A39)-1))+TIME(0,30,0), "h:mm AM/PM") & " - " & TEXT(TIMEVALUE(MID(A39,FIND("- ",A39)+2,99))+TIME(0,30,0), "h:mm AM/PM") -> 7:30 PM - 8:00 PM | B40: 1 | C40: 1 | D40: 1 | E40: 1 | F40: 1
A41: =TEXT(TIMEVALUE(LEFT(A40,FIND(" -",A40)-1))+TIME(0,30,0), "h:mm AM/PM") & " - " & TEXT(TIMEVALUE(MID(A40,FIND("- ",A40)+2,99))+TIME(0,30,0), "h:mm AM/PM") -> 8:00 PM - 8:30 PM | B41: 1 | C41: 1 | D41: 1 | E41: 1 | F41: 1 | G41: 1 | H41: 1
A42: =TEXT(TIMEVALUE(LEFT(A41,FIND(" -",A41)-1))+TIME(0,30,0), "h:mm AM/PM") & " - " & TEXT(TIMEVALUE(MID(A41,FIND("- ",A41)+2,99))+TIME(0,30,0), "h:mm AM/PM") -> 8:30 PM - 9:00 PM | B42: 1 | C42: 1 | D42: 1 | E42: 1 | F42: 1 | G42: 1 | H42: 1
A43: =TEXT(TIMEVALUE(LEFT(A42,FIND(" -",A42)-1))+TIME(0,30,0), "h:mm AM/PM") & " - " & TEXT(TIMEVALUE(MID(A42,FIND("- ",A42)+2,99))+TIME(0,30,0), "h:mm AM/PM") -> 9:00 PM - 9:30 PM | B43: 1 | C43: 1 | D43: 1 | E43: 1 | F43: 1 | G43: 1 | H43: 1

Sheet Eddie Nguyen
A1: Step 1: Rename the sheet name with your name, for example 'Member 3 Name' to 'Your Name' | J1: Time Zone
A2: Step 2: Choose your time zone from yellow drop down box | J2: PST
A3: Step 3: Enter '1' in all 30-minute slots you're NOT available in orange area | J3: {=_xlfn.SWITCH(J2,"PST",0,"MST",1,"CST",2,"EST",3,0)} -> 0
A6: Time | B6: Monday | C6: Tuesday | D6: Wednesday | E6: Thursday | F6: Friday | G6: Saturday | H6: Sunday
A7: =TEXT(TIME(3,0,0)+$J$3/24,"h:mm AM/PM") & " - " & TEXT(TIME(3,30,0)+$J$3/24,"h:mm AM/PM") -> 3:00 AM - 3:30 AM | B7: 1 | C7: 1 | D7: 1 | E7: 1 | F7: 1 | G7: 1 | H7: 1
A8: =TEXT(TIMEVALUE(LEFT(A7,FIND(" -",A7)-1))+TIME(0,30,0), "h:mm AM/PM") & " - " & TEXT(TIMEVALUE(MID(A7,FIND("- ",A7)+2,99))+TIME(0,30,0), "h:mm AM/PM") -> 3:30 AM - 4:00 AM | B8: 1 | C8: 1 | D8: 1 | E8: 1 | F8: 1 | G8: 1 | H8: 1
A9: =TEXT(TIMEVALUE(LEFT(A8,FIND(" -",A8)-1))+TIME(0,30,0), "h:mm AM/PM") & " - " & TEXT(TIMEVALUE(MID(A8,FIND("- ",A8)+2,99))+TIME(0,30,0), "h:mm AM/PM") -> 4:00 AM - 4:30 AM | B9: 1 | C9: 1 | D9: 1 | E9: 1 | F9: 1 | G9: 1 | H9: 1
A10: =TEXT(TIMEVALUE(LEFT(A9,FIND(" -",A9)-1))+TIME(0,30,0), "h:mm AM/PM") & " - " & TEXT(TIMEVALUE(MID(A9,FIND("- ",A9)+2,99))+TIME(0,30,0), "h:mm AM/PM") -> 4:30 AM - 5:00 AM | B10: 1 | C10: 1 | D10: 1 | E10: 1 | F10: 1 | G10: 1 | H10: 1
A11: =TEXT(TIMEVALUE(LEFT(A10,FIND(" -",A10)-1))+TIME(0,30,0), "h:mm AM/PM") & " - " & TEXT(TIMEVALUE(MID(A10,FIND("- ",A10)+2,99))+TIME(0,30,0), "h:mm AM/PM") -> 5:00 AM - 5:30 AM | B11: 1 | C11: 1 | D11: 1 | E11: 1 | F11: 1 | G11: 1 | H11: 1
A12: =TEXT(TIMEVALUE(LEFT(A11,FIND(" -",A11)-1))+TIME(0,30,0), "h:mm AM/PM") & " - " & TEXT(TIMEVALUE(MID(A11,FIND("- ",A11)+2,99))+TIME(0,30,0), "h:mm AM/PM") -> 5:30 AM - 6:00 AM | B12: 1 | C12: 1 | D12: 1 | E12: 1 | F12: 1 | G12: 1 | H12: 1
A13: =TEXT(TIMEVALUE(LEFT(A12,FIND(" -",A12)-1))+TIME(0,30,0), "h:mm AM/PM") & " - " & TEXT(TIMEVALUE(MID(A12,FIND("- ",A12)+2,99))+TIME(0,30,0), "h:mm AM/PM") -> 6:00 AM - 6:30 AM | B13: 1 | C13: 1 | D13: 1 | E13: 1 | F13: 1 | G13: 1 | H13: 1
A14: =TEXT(TIMEVALUE(LEFT(A13,FIND(" -",A13)-1))+TIME(0,30,0), "h:mm AM/PM") & " - " & TEXT(TIMEVALUE(MID(A13,FIND("- ",A13)+2,99))+TIME(0,30,0), "h:mm AM/PM") -> 6:30 AM - 7:00 AM | B14: 1 | C14: 1 | D14: 1 | E14: 1 | F14: 1 | G14: 1 | H14: 1
A15: =TEXT(TIMEVALUE(LEFT(A14,FIND(" -",A14)-1))+TIME(0,30,0), "h:mm AM/PM") & " - " & TEXT(TIMEVALUE(MID(A14,FIND("- ",A14)+2,99))+TIME(0,30,0), "h:mm AM/PM") -> 7:00 AM - 7:30 AM | B15: 1 | C15: 1 | D15: 1 | E15: 1 | F15: 1 | G15: 1 | H15: 1
A16: =TEXT(TIMEVALUE(LEFT(A15,FIND(" -",A15)-1))+TIME(0,30,0), "h:mm AM/PM") & " - " & TEXT(TIMEVALUE(MID(A15,FIND("- ",A15)+2,99))+TIME(0,30,0), "h:mm AM/PM") -> 7:30 AM - 8:00 AM | B16: 1 | C16: 1 | D16: 1 | E16: 1 | F16: 1 | G16: 1 | H16: 1
A17: =TEXT(TIMEVALUE(LEFT(A16,FIND(" -",A16)-1))+TIME(0,30,0), "h:mm AM/PM") & " - " & TEXT(TIMEVALUE(MID(A16,FIND("- ",A16)+2,99))+TIME(0,30,0), "h:mm AM/PM") -> 8:00 AM - 8:30 AM | B17: 1 | C17: 1 | D17: 1 | E17: 1 | F17: 1 | G17: 1 | H17: 1
A18: =TEXT(TIMEVALUE(LEFT(A17,FIND(" -",A17)-1))+TIME(0,30,0), "h:mm AM/PM") & " - " & TEXT(TIMEVALUE(MID(A17,FIND("- ",A17)+2,99))+TIME(0,30,0), "h:mm AM/PM") -> 8:30 AM - 9:00 AM | B18: 1 | C18: 1 | D18: 1 | E18: 1 | F18: 1 | G18: 1 | H18: 1
A19: =TEXT(TIMEVALUE(LEFT(A18,FIND(" -",A18)-1))+TIME(0,30,0), "h:mm AM/PM") & " - " & TEXT(TIMEVALUE(MID(A18,FIND("- ",A18)+2,99))+TIME(0,30,0), "h:mm AM/PM") -> 9:00 AM - 9:30 AM | B19: 1 | C19: 1 | D19: 1 | E19: 1 | F19: 1 | G19: 1 | H19: 1
A20: =TEXT(TIMEVALUE(LEFT(A19,FIND(" -",A19)-1))+TIME(0,30,0), "h:mm AM/PM") & " - " & TEXT(TIMEVALUE(MID(A19,FIND("- ",A19)+2,99))+TIME(0,30,0), "h:mm AM/PM") -> 9:30 AM - 10:00 AM | B20: 1 | C20: 1 | D20: 1 | E20: 1
A21: =TEXT(TIMEVALUE(LEFT(A20,FIND(" -",A20)-1))+TIME(0,30,0), "h:mm AM/PM") & " - " & TEXT(TIMEVALUE(MID(A20,FIND("- ",A20)+2,99))+TIME(0,30,0), "h:mm AM/PM") -> 10:00 AM - 10:30 AM | B21: 1 | C21: 1 | D21: 1 | E21: 1
A22: =TEXT(TIMEVALUE(LEFT(A21,FIND(" -",A21)-1))+TIME(0,30,0), "h:mm AM/PM") & " - " & TEXT(TIMEVALUE(MID(A21,FIND("- ",A21)+2,99))+TIME(0,30,0), "h:mm AM/PM") -> 10:30 AM - 11:00 AM | B22: 1 | C22: 1 | D22: 1 | E22: 1
A23: =TEXT(TIMEVALUE(LEFT(A22,FIND(" -",A22)-1))+TIME(0,30,0), "h:mm AM/PM") & " - " & TEXT(TIMEVALUE(MID(A22,FIND("- ",A22)+2,99))+TIME(0,30,0), "h:mm AM/PM") -> 11:00 AM - 11:30 AM | B23: 1 | C23: 1 | D23: 1 | E23: 1
A24: =TEXT(TIMEVALUE(LEFT(A23,FIND(" -",A23)-1))+TIME(0,30,0), "h:mm AM/PM") & " - " & TEXT(TIMEVALUE(MID(A23,FIND("- ",A23)+2,99))+TIME(0,30,0), "h:mm AM/PM") -> 11:30 AM - 12:00 PM | B24: 1 | C24: 1 | D24: 1 | E24: 1
A25: =TEXT(TIMEVALUE(LEFT(A24,FIND(" -",A24)-1))+TIME(0,30,0), "h:mm AM/PM") & " - " & TEXT(TIMEVALUE(MID(A24,FIND("- ",A24)+2,99))+TIME(0,30,0), "h:mm AM/PM") -> 12:00 PM - 12:30 PM
A26: =TEXT(TIMEVALUE(LEFT(A25,FIND(" -",A25)-1))+TIME(0,30,0), "h:mm AM/PM") & " - " & TEXT(TIMEVALUE(MID(A25,FIND("- ",A25)+2,99))+TIME(0,30,0), "h:mm AM/PM") -> 12:30 PM - 1:00 PM
A27: =TEXT(TIMEVALUE(LEFT(A26,FIND(" -",A26)-1))+TIME(0,30,0), "h:mm AM/PM") & " - " & TEXT(TIMEVALUE(MID(A26,FIND("- ",A26)+2,99))+TIME(0,30,0), "h:mm AM/PM") -> 1:00 PM - 1:30 PM
A28: =TEXT(TIMEVALUE(LEFT(A27,FIND(" -",A27)-1))+TIME(0,30,0), "h:mm AM/PM") & " - " & TEXT(TIMEVALUE(MID(A27,FIND("- ",A27)+2,99))+TIME(0,30,0), "h:mm AM/PM") -> 1:30 PM - 2:00 PM
A29: =TEXT(TIMEVALUE(LEFT(A28,FIND(" -",A28)-1))+TIME(0,30,0), "h:mm AM/PM") & " - " & TEXT(TIMEVALUE(MID(A28,FIND("- ",A28)+2,99))+TIME(0,30,0), "h:mm AM/PM") -> 2:00 PM - 2:30 PM
A30: =TEXT(TIMEVALUE(LEFT(A29,FIND(" -",A29)-1))+TIME(0,30,0), "h:mm AM/PM") & " - " & TEXT(TIMEVALUE(MID(A29,FIND("- ",A29)+2,99))+TIME(0,30,0), "h:mm AM/PM") -> 2:30 PM - 3:00 PM
A31: =TEXT(TIMEVALUE(LEFT(A30,FIND(" -",A30)-1))+TIME(0,30,0), "h:mm AM/PM") & " - " & TEXT(TIMEVALUE(MID(A30,FIND("- ",A30)+2,99))+TIME(0,30,0), "h:mm AM/PM") -> 3:00 PM - 3:30 PM
A32: =TEXT(TIMEVALUE(LEFT(A31,FIND(" -",A31)-1))+TIME(0,30,0), "h:mm AM/PM") & " - " & TEXT(TIMEVALUE(MID(A31,FIND("- ",A31)+2,99))+TIME(0,30,0), "h:mm AM/PM") -> 3:30 PM - 4:00 PM
A33: =TEXT(TIMEVALUE(LEFT(A32,FIND(" -",A32)-1))+TIME(0,30,0), "h:mm AM/PM") & " - " & TEXT(TIMEVALUE(MID(A32,FIND("- ",A32)+2,99))+TIME(0,30,0), "h:mm AM/PM") -> 4:00 PM - 4:30 PM | C33: 1 | E33: 1
A34: =TEXT(TIMEVALUE(LEFT(A33,FIND(" -",A33)-1))+TIME(0,30,0), "h:mm AM/PM") & " - " & TEXT(TIMEVALUE(MID(A33,FIND("- ",A33)+2,99))+TIME(0,30,0), "h:mm AM/PM") -> 4:30 PM - 5:00 PM | C34: 1 | E34: 1
A35: =TEXT(TIMEVALUE(LEFT(A34,FIND(" -",A34)-1))+TIME(0,30,0), "h:mm AM/PM") & " - " & TEXT(TIMEVALUE(MID(A34,FIND("- ",A34)+2,99))+TIME(0,30,0), "h:mm AM/PM") -> 5:00 PM - 5:30 PM | C35: 1 | E35: 1
A36: =TEXT(TIMEVALUE(LEFT(A35,FIND(" -",A35)-1))+TIME(0,30,0), "h:mm AM/PM") & " - " & TEXT(TIMEVALUE(MID(A35,FIND("- ",A35)+2,99))+TIME(0,30,0), "h:mm AM/PM") -> 5:30 PM - 6:00 PM | C36: 1 | E36: 1
A37: =TEXT(TIMEVALUE(LEFT(A36,FIND(" -",A36)-1))+TIME(0,30,0), "h:mm AM/PM") & " - " & TEXT(TIMEVALUE(MID(A36,FIND("- ",A36)+2,99))+TIME(0,30,0), "h:mm AM/PM") -> 6:00 PM - 6:30 PM | C37: 1 | E37: 1
A38: =TEXT(TIMEVALUE(LEFT(A37,FIND(" -",A37)-1))+TIME(0,30,0), "h:mm AM/PM") & " - " & TEXT(TIMEVALUE(MID(A37,FIND("- ",A37)+2,99))+TIME(0,30,0), "h:mm AM/PM") -> 6:30 PM - 7:00 PM | C38: 1 | E38: 1
A39: =TEXT(TIMEVALUE(LEFT(A38,FIND(" -",A38)-1))+TIME(0,30,0), "h:mm AM/PM") & " - " & TEXT(TIMEVALUE(MID(A38,FIND("- ",A38)+2,99))+TIME(0,30,0), "h:mm AM/PM") -> 7:00 PM - 7:30 PM | C39: 1 | E39: 1
A40: =TEXT(TIMEVALUE(LEFT(A39,FIND(" -",A39)-1))+TIME(0,30,0), "h:mm AM/PM") & " - " & TEXT(TIMEVALUE(MID(A39,FIND("- ",A39)+2,99))+TIME(0,30,0), "h:mm AM/PM") -> 7:30 PM - 8:00 PM | C40: 1 | E40: 1
A41: =TEXT(TIMEVALUE(LEFT(A40,FIND(" -",A40)-1))+TIME(0,30,0), "h:mm AM/PM") & " - " & TEXT(TIMEVALUE(MID(A40,FIND("- ",A40)+2,99))+TIME(0,30,0), "h:mm AM/PM") -> 8:00 PM - 8:30 PM | C41: 1 | E41: 1
A42: =TEXT(TIMEVALUE(LEFT(A41,FIND(" -",A41)-1))+TIME(0,30,0), "h:mm AM/PM") & " - " & TEXT(TIMEVALUE(MID(A41,FIND("- ",A41)+2,99))+TIME(0,30,0), "h:mm AM/PM") -> 8:30 PM - 9:00 PM | B42: 1 | C42: 1 | D42: 1 | E42: 1 | F42: 1 | G42: 1 | H42: 1
...

Sheet Johnny Lin
A1: Step 1: Rename the sheet name with your name, for example 'Member 4 Name' to 'Your Name' | J1: Time Zone
A2: Step 2: Choose your time zone from yellow drop down box | J2: PST
A3: Step 3: Enter '1' in all 30-minute slots you're NOT available in orange area | J3: 0
A6: Time | B6: Monday | C6: Tuesday | D6: Wednesday | E6: Thursday | F6: Friday | G6: Saturday | H6: Sunday
A7: 3:00 AM - 3:30 AM | B7: 1 | C7: 1 | D7: 1 | E7: 1 | F7: 1 | G7: 1 | H7: 1
A8: 3:30 AM - 4:00 AM | B8: 1 | C8: 1 | D8: 1 | E8: 1 | F8: 1 | G8: 1 | H8: 1
A9: 4:00 AM - 4:30 AM | B9: 1 | C9: 1 | D9: 1 | E9: 1 | F9: 1 | G9: 1 | H9: 1
A10: 4:30 AM - 5:00 AM | B10: 1 | C10: 1 | D10: 1 | E10: 1 | F10: 1 | G10: 1 | H10: 1
A11: 5:00 AM - 5:30 AM | B11: 1 | C11: 1 | D11: 1 | E11: 1 | F11: 1 | G11: 1 | H11: 1
A12: 5:30 AM - 6:00 AM | B12: 1 | C12: 1 | D12: 1 | E12: 1 | F12: 1 | G12: 1 | H12: 1
A13: 6:00 AM - 6:30 AM | B13: 1 | C13: 1 | D13: 1 | E13: 1 | F13: 1 | G13: 1 | H13: 1
A14: 6:30 AM - 7:00 AM | B14: 1 | C14: 1 | D14: 1 | E14: 1 | F14: 1 | G14: 1 | H14: 1
A15: 7:00 AM - 7:30 AM | B15: 1 | C15: 1 | D15: 1 | E15: 1 | F15: 1 | G15: 1 | H15: 1
A16: 7:30 AM - 8:00 AM | B16: 1 | C16: 1 | D16: 1 | E16: 1 | F16: 1 | G16: 1 | H16: 1
A17: 8:00 AM - 8:30 AM | B17: 1 | C17: 1 | D17: 1 | E17: 1 | F17: 1 | G17: 1 | H17: 1
A18: 8:30 AM - 9:00 AM | B18: 1 | C18: 1 | D18: 1 | E18: 1 | F18: 1 | G18: 1 | H18: 1
A19: 9:00 AM - 9:30 AM | C19: 1 | E19: 1
A20: 9:30 AM - 10:00 AM | C20: 1 | E20: 1
A21: 10:00 AM - 10:30 AM | C21: 1 | E21: 1
A22: 10:30 AM - 11:00 AM | C22: 1 | E22: 1
A23: 11:00 AM - 11:30 AM | C23: 1 | E23: 1
A24: 11:30 AM - 12:00 PM | C24: 1 | E24: 1
A25: 12:00 PM - 12:30 PM | C25: 1 | E25: 1
A26: 12:30 PM - 1:00 PM | C26: 1 | E26: 1
A27: 1:00 PM - 1:30 PM | C27: 1 | E27: 1
A28: 1:30 PM - 2:00 PM | C28: 1 | E28: 1
A29: 2:00 PM - 2:30 PM | C29: 1 | E29: 1
A30: 2:30 PM - 3:00 PM | C30: 1 | D30: 1 | E30: 1
A31: 3:00 PM - 3:30 PM | C31: 1 | D31: 1 | E31: 1
A32: 3:30 PM - 4:00 PM | C32: 1 | D32: 1 | E32: 1
A33: 4:00 PM - 4:30 PM | C33: 1 | D33: 1 | E33: 1
A34: 4:30 PM - 5:00 PM | C34: 1 | D34: 1 | E34: 1
A35: 5:00 PM - 5:30 PM | C35: 1 | D35: 1 | E35: 1
A36: 5:30 PM - 6:00 PM | C36: 1 | E36: 1
A37: 6:00 PM - 6:30 PM | C37: 1 | E37: 1
A38: 6:30 PM - 7:00 PM | C38: 1 | E38: 1
A39: 7:00 PM - 7:30 PM
A40: 7:30 PM - 8:00 PM
A41: 8:00 PM - 8:30 PM
A42: 8:30 PM - 9:00 PM
...

Sheet Ashley Hui
A1: Step 1: Rename the sheet name with your name, for example 'Member 5 Name' to 'Your Name' | J1: Time Zone
A2: Step 2: Choose your time zone from yellow drop down box | J2: CST
A3: Step 3: Enter '1' in all 30-minute slots you're NOT available in orange area | J3: {=_xlfn.SWITCH(J2,"PST",0,"MST",1,"CST",2,"EST",3,0)} -> 2
A6: Time | B6: Monday | C6: Tuesday | D6: Wednesday | E6: Thursday | F6: Friday | G6: Saturday | H6: Sunday
A7: =TEXT(TIME(3,0,0)+$J$3/24,"h:mm AM/PM") & " - " & TEXT(TIME(3,30,0)+$J$3/24,"h:mm AM/PM") -> 5:00 AM - 5:30 AM | B7: 1 | C7: 1 | D7: 1 | E7: 1 | F7: 1
A8: =TEXT(TIMEVALUE(LEFT(A7,FIND(" -",A7)-1))+TIME(0,30,0), "h:mm AM/PM") & " - " & TEXT(TIMEVALUE(MID(A7,FIND("- ",A7)+2,99))+TIME(0,30,0), "h:mm AM/PM") -> 5:30 AM - 6:00 AM | B8: 1 | C8: 1 | D8: 1 | E8: 1 | F8: 1
A9: =TEXT(TIMEVALUE(LEFT(A8,FIND(" -",A8)-1))+TIME(0,30,0), "h:mm AM/PM") & " - " & TEXT(TIMEVALUE(MID(A8,FIND("- ",A8)+2,99))+TIME(0,30,0), "h:mm AM/PM") -> 6:00 AM - 6:30 AM | B9: 1 | C9: 1 | D9: 1 | E9: 1 | F9: 1
A10: =TEXT(TIMEVALUE(LEFT(A9,FIND(" -",A9)-1))+TIME(0,30,0), "h:mm AM/PM") & " - " & TEXT(TIMEVALUE(MID(A9,FIND("- ",A9)+2,99))+TIME(0,30,0), "h:mm AM/PM") -> 6:30 AM - 7:00 AM | B10: 1 | C10: 1 | D10: 1 | E10: 1 | F10: 1
A11: =TEXT(TIMEVALUE(LEFT(A10,FIND(" -",A10)-1))+TIME(0,30,0), "h:mm AM/PM") & " - " & TEXT(TIMEVALUE(MID(A10,FIND("- ",A10)+2,99))+TIME(0,30,0), "h:mm AM/PM") -> 7:00 AM - 7:30 AM | B11: 1 | C11: 1 | D11: 1 | E11: 1 | F11: 1
A12: =TEXT(TIMEVALUE(LEFT(A11,FIND(" -",A11)-1))+TIME(0,30,0), "h:mm AM/PM") & " - " & TEXT(TIMEVALUE(MID(A11,FIND("- ",A11)+2,99))+TIME(0,30,0), "h:mm AM/PM") -> 7:30 AM - 8:00 AM | B12: 1 | C12: 1 | D12: 1 | E12: 1 | F12: 1
A13: =TEXT(TIMEVALUE(LEFT(A12,FIND(" -",A12)-1))+TIME(0,30,0), "h:mm AM/PM") & " - " & TEXT(TIMEVALUE(MID(A12,FIND("- ",A12)+2,99))+TIME(0,30,0), "h:mm AM/PM") -> 8:00 AM - 8:30 AM | B13: 1 | C13: 1 | D13: 1 | E13: 1 | F13: 1
A14: =TEXT(TIMEVALUE(LEFT(A13,FIND(" -",A13)-1))+TIME(0,30,0), "h:mm AM/PM") & " - " & TEXT(TIMEVALUE(MID(A13,FIND("- ",A13)+2,99))+TIME(0,30,0), "h:mm AM/PM") -> 8:30 AM - 9:00 AM | B14: 1 | C14: 1 | D14: 1 | E14: 1 | F14: 1
A15: =TEXT(TIMEVALUE(LEFT(A14,FIND(" -",A14)-1))+TIME(0,30,0), "h:mm AM/PM") & " - " & TEXT(TIMEVALUE(MID(A14,FIND("- ",A14)+2,99))+TIME(0,30,0), "h:mm AM/PM") -> 9:00 AM - 9:30 AM | B15: 1 | C15: 1 | D15: 1 | E15: 1 | F15: 1
A16: =TEXT(TIMEVALUE(LEFT(A15,FIND(" -",A15)-1))+TIME(0,30,0), "h:mm AM/PM") & " - " & TEXT(TIMEVALUE(MID(A15,FIND("- ",A15)+2,99))+TIME(0,30,0), "h:mm AM/PM") -> 9:30 AM - 10:00 AM | B16: 1 | C16: 1 | D16: 1 | E16: 1 | F16: 1
A17: =TEXT(TIMEVALUE(LEFT(A16,FIND(" -",A16)-1))+TIME(0,30,0), "h:mm AM/PM") & " - " & TEXT(TIMEVALUE(MID(A16,FIND("- ",A16)+2,99))+TIME(0,30,0), "h:mm AM/PM") -> 10:00 AM - 10:30 AM | B17: 1 | C17: 1 | D17: 1 | E17: 1 | F17: 1
A18: =TEXT(TIMEVALUE(LEFT(A17,FIND(" -",A17)-1))+TIME(0,30,0), "h:mm AM/PM") & " - " & TEXT(TIMEVALUE(MID(A17,FIND("- ",A17)+2,99))+TIME(0,30,0), "h:mm AM/PM") -> 10:30 AM - 11:00 AM | B18: 1 | C18: 1 | D18: 1 | E18: 1 | F18: 1
A19: =TEXT(TIMEVALUE(LEFT(A18,FIND(" -",A18)-1))+TIME(0,30,0), "h:mm AM/PM") & " - " & TEXT(TIMEVALUE(MID(A18,FIND("- ",A18)+2,99))+TIME(0,30,0), "h:mm AM/PM") -> 11:00 AM - 11:30 AM | B19: 1 | C19: 1 | D19: 1 | E19: 1 | F19: 1
A20: =TEXT(TIMEVALUE(LEFT(A19,FIND(" -",A19)-1))+TIME(0,30,0), "h:mm AM/PM") & " - " & TEXT(TIMEVALUE(MID(A19,FIND("- ",A19)+2,99))+TIME(0,30,0), "h:mm AM/PM") -> 11:30 AM - 12:00 PM | B20: 1 | C20: 1 | D20: 1 | E20: 1 | F20: 1
A21: =TEXT(TIMEVALUE(LEFT(A20,FIND(" -",A20)-1))+TIME(0,30,0), "h:mm AM/PM") & " - " & TEXT(TIMEVALUE(MID(A20,FIND("- ",A20)+2,99))+TIME(0,30,0), "h:mm AM/PM") -> 12:00 PM - 12:30 PM | B21: 1 | C21: 1 | D21: 1 | E21: 1
A22: =TEXT(TIMEVALUE(LEFT(A21,FIND(" -",A21)-1))+TIME(0,30,0), "h:mm AM/PM") & " - " & TEXT(TIMEVALUE(MID(A21,FIND("- ",A21)+2,99))+TIME(0,30,0), "h:mm AM/PM") -> 12:30 PM - 1:00 PM | B22: 1 | C22: 1 | D22: 1 | E22: 1
A23: =TEXT(TIMEVALUE(LEFT(A22,FIND(" -",A22)-1))+TIME(0,30,0), "h:mm AM/PM") & " - " & TEXT(TIMEVALUE(MID(A22,FIND("- ",A22)+2,99))+TIME(0,30,0), "h:mm AM/PM") -> 1:00 PM - 1:30 PM
A24: =TEXT(TIMEVALUE(LEFT(A23,FIND(" -",A23)-1))+TIME(0,30,0), "h:mm AM/PM") & " - " & TEXT(TIMEVALUE(MID(A23,FIND("- ",A23)+2,99))+TIME(0,30,0), "h:mm AM/PM") -> 1:30 PM - 2:00 PM
A25: =TEXT(TIMEVALUE(LEFT(A24,FIND(" -",A24)-1))+TIME(0,30,0), "h:mm AM/PM") & " - " & TEXT(TIMEVALUE(MID(A24,FIND("- ",A24)+2,99))+TIME(0,30,0), "h:mm AM/PM") -> 2:00 PM - 2:30 PM | B25: 1 | C25: 1 | D25: 1 | E25: 1
A26: =TEXT(TIMEVALUE(LEFT(A25,FIND(" -",A25)-1))+TIME(0,30,0), "h:mm AM/PM") & " - " & TEXT(TIMEVALUE(MID(A25,FIND("- ",A25)+2,99))+TIME(0,30,0), "h:mm AM/PM") -> 2:30 PM - 3:00 PM | B26: 1 | C26: 1 | D26: 1 | E26: 1
A27: =TEXT(TIMEVALUE(LEFT(A26,FIND(" -",A26)-1))+TIME(0,30,0), "h:mm AM/PM") & " - " & TEXT(TIMEVALUE(MID(A26,FIND("- ",A26)+2,99))+TIME(0,30,0), "h:mm AM/PM") -> 3:00 PM - 3:30 PM | B27: 1 | C27: 1 | D27: 1 | E27: 1
A28: =TEXT(TIMEVALUE(LEFT(A27,FIND(" -",A27)-1))+TIME(0,30,0), "h:mm AM/PM") & " - " & TEXT(TIMEVALUE(MID(A27,FIND("- ",A27)+2,99))+TIME(0,30,0), "h:mm AM/PM") -> 3:30 PM - 4:00 PM | B28: 1 | C28: 1 | D28: 1 | E28: 1
A29: =TEXT(TIMEVALUE(LEFT(A28,FIND(" -",A28)-1))+TIME(0,30,0), "h:mm AM/PM") & " - " & TEXT(TIMEVALUE(MID(A28,FIND("- ",A28)+2,99))+TIME(0,30,0), "h:mm AM/PM") -> 4:00 PM - 4:30 PM | C29: 1 | E29: 1
A30: =TEXT(TIMEVALUE(LEFT(A29,FIND(" -",A29)-1))+TIME(0,30,0), "h:mm AM/PM") & " - " & TEXT(TIMEVALUE(MID(A29,FIND("- ",A29)+2,99))+TIME(0,30,0), "h:mm AM/PM") -> 4:30 PM - 5:00 PM | C30: 1 | E30: 1
A31: =TEXT(TIMEVALUE(LEFT(A30,FIND(" -",A30)-1))+TIME(0,30,0), "h:mm AM/PM") & " - " & TEXT(TIMEVALUE(MID(A30,FIND("- ",A30)+2,99))+TIME(0,30,0), "h:mm AM/PM") -> 5:00 PM - 5:30 PM | C31: 1 | E31: 1
A32: =TEXT(TIMEVALUE(LEFT(A31,FIND(" -",A31)-1))+TIME(0,30,0), "h:mm AM/PM") & " - " & TEXT(TIMEVALUE(MID(A31,FIND("- ",A31)+2,99))+TIME(0,30,0), "h:mm AM/PM") -> 5:30 PM - 6:00 PM | C32: 1 | E32: 1
A33: =TEXT(TIMEVALUE(LEFT(A32,FIND(" -",A32)-1))+TIME(0,30,0), "h:mm AM/PM") & " - " & TEXT(TIMEVALUE(MID(A32,FIND("- ",A32)+2,99))+TIME(0,30,0), "h:mm AM/PM") -> 6:00 PM - 6:30 PM
A34: =TEXT(TIMEVALUE(LEFT(A33,FIND(" -",A33)-1))+TIME(0,30,0), "h:mm AM/PM") & " - " & TEXT(TIMEVALUE(MID(A33,FIND("- ",A33)+2,99))+TIME(0,30,0), "h:mm AM/PM") -> 6:30 PM - 7:00 PM
A35: =TEXT(TIMEVALUE(LEFT(A34,FIND(" -",A34)-1))+TIME(0,30,0), "h:mm AM/PM") & " - " & TEXT(TIMEVALUE(MID(A34,FIND("- ",A34)+2,99))+TIME(0,30,0), "h:mm AM/PM") -> 7:00 PM - 7:30 PM
A36: =TEXT(TIMEVALUE(LEFT(A35,FIND(" -",A35)-1))+TIME(0,30,0), "h:mm AM/PM") & " - " & TEXT(TIMEVALUE(MID(A35,FIND("- ",A35)+2,99))+TIME(0,30,0), "h:mm AM/PM") -> 7:30 PM - 8:00 PM
A37: =TEXT(TIMEVALUE(LEFT(A36,FIND(" -",A36)-1))+TIME(0,30,0), "h:mm AM/PM") & " - " & TEXT(TIMEVALUE(MID(A36,FIND("- ",A36)+2,99))+TIME(0,30,0), "h:mm AM/PM") -> 8:00 PM - 8:30 PM | B37: 1 | C37: 1 | D37: 1 | E37: 1 | F37: 1 | G37: 1 | H37: 1
A38: =TEXT(TIMEVALUE(LEFT(A37,FIND(" -",A37)-1))+TIME(0,30,0), "h:mm AM/PM") & " - " & TEXT(TIMEVALUE(MID(A37,FIND("- ",A37)+2,99))+TIME(0,30,0), "h:mm AM/PM") -> 8:30 PM - 9:00 PM | B38: 1 | C38: 1 | D38: 1 | E38: 1 | F38: 1 | G38: 1 | H38: 1
A39: =TEXT(TIMEVALUE(LEFT(A38,FIND(" -",A38)-1))+TIME(0,30,0), "h:mm AM/PM") & " - " & TEXT(TIMEVALUE(MID(A38,FIND("- ",A38)+2,99))+TIME(0,30,0), "h:mm AM/PM") -> 9:00 PM - 9:30 PM | B39: 1 | C39: 1 | D39: 1 | E39: 1 | F39: 1 | G39: 1 | H39: 1
A40: =TEXT(TIMEVALUE(LEFT(A39,FIND(" -",A39)-1))+TIME(0,30,0), "h:mm AM/PM") & " - " & TEXT(TIMEVALUE(MID(A39,FIND("- ",A39)+2,99))+TIME(0,30,0), "h:mm AM/PM") -> 9:30 PM - 10:00 PM | B40: 1 | C40: 1 | D40: 1 | E40: 1 | F40: 1 | G40: 1 | H40: 1
A41: =TEXT(TIMEVALUE(LEFT(A40,FIND(" -",A40)-1))+TIME(0,30,0), "h:mm AM/PM") & " - " & TEXT(TIMEVALUE(MID(A40,FIND("- ",A40)+2,99))+TIME(0,30,0), "h:mm AM/PM") -> 10:00 PM - 10:30 PM | B41: 1 | C41: 1 | D41: 1 | E41: 1 | F41: 1 | G41: 1 | H41: 1
A42: =TEXT(TIMEVALUE(LEFT(A41,FIND(" -",A41)-1))+TIME(0,30,0), "h:mm AM/PM") & " - " & TEXT(TIMEVALUE(MID(A41,FIND("- ",A41)+2,99))+TIME(0,30,0), "h:mm AM/PM") -> 10:30 PM - 11:00 PM | B42: 1 | C42: 1 | D42: 1 | E42: 1 | F42: 1 | G42: 1 | H42: 1
...

Sheet Team Availability
A1: Step 1. Choose your time zone from yellow drop down box | J1: Time Zone
J2: PST
A3: The darker the cell, the more people are available. Black cells mean all members are free to meet. | J3: {=_xlfn.SWITCH(J2,"PST",0,"MST",1,"CST",2,"EST",3,0)} -> 0
A6: Time | B6: Monday | C6: Tuesday | D6: Wednesday | E6: Thursday | F6: Friday | G6: Saturday | H6: Sunday
A7: =TEXT(TIME(3,0,0)+$J$3/24,"h:mm AM/PM") & " - " & TEXT(TIME(3,30,0)+$J$3/24,"h:mm AM/PM") -> 3:00 AM - 3:30 AM | B7: =IF(COUNTA('Jenny Li'!B7,'Huiyu Yie'!B7,'Eddie Nguyen'!B7,'Johnny Lin'!B7,'Ashley Hui'!B7)=0,0,COUNTA('Jenny Li'!B7,'Huiyu Yie'!B7,'Eddie Nguyen'!B7,'Johnny Lin'!B7,'Ashley Hui'!B7)) -> 5 | C7: =IF(COUNTA('Jenny Li'!C7,'Huiyu Yie'!C7,'Eddie Nguyen'!C7,'Johnny Lin'!C7,'Ashley Hui'!C7)=0,0,COUNTA('Jenny Li'!C7,'Huiyu Yie'!C7,'Eddie Nguyen'!C7,'Johnny Lin'!C7,'Ashley Hui'!C7)) -> 5 | D7: =IF(COUNTA('Jenny Li'!D7,'Huiyu Yie'!D7,'Eddie Nguyen'!D7,'Johnny Lin'!D7,'Ashley Hui'!D7)=0,0,COUNTA('Jenny Li'!D7,'Huiyu Yie'!D7,'Eddie Nguyen'!D7,'Johnny Lin'!D7,'Ashley Hui'!D7)) -> 5 | E7: =IF(COUNTA('Jenny Li'!E7,'Huiyu Yie'!E7,'Eddie Nguyen'!E7,'Johnny Lin'!E7,'Ashley Hui'!E7)=0,0,COUNTA('Jenny Li'!E7,'Huiyu Yie'!E7,'Eddie Nguyen'!E7,'Johnny Lin'!E7,'Ashley Hui'!E7)) -> 5 | F7: =IF(COUNTA('Jenny Li'!F7,'Huiyu Yie'!F7,'Eddie Nguyen'!F7,'Johnny Lin'!F7,'Ashley Hui'!F7)=0,0,COUNTA('Jenny Li'!F7,'Huiyu Yie'!F7,'Eddie Nguyen'!F7,'Johnny Lin'!F7,'Ashley Hui'!F7)) -> 5 | G7: =IF(COUNTA('Jenny Li'!G7,'Huiyu Yie'!G7,'Eddie Nguyen'!G7,'Johnny Lin'!G7,'Ashley Hui'!G7)=0,0,COUNTA('Jenny Li'!G7,'Huiyu Yie'!G7,'Eddie Nguyen'!G7,'Johnny Lin'!G7,'Ashley Hui'!G7)) -> 4 | H7: =IF(COUNTA('Jenny Li'!H7,'Huiyu Yie'!H7,'Eddie Nguyen'!H7,'Johnny Lin'!H7,'Ashley Hui'!H7)=0,0,COUNTA('Jenny Li'!H7,'Huiyu Yie'!H7,'Eddie Nguyen'!H7,'Johnny Lin'!H7,'Ashley Hui'!H7)) -> 4
A8: =TEXT(TIMEVALUE(LEFT(A7,FIND(" -",A7)-1))+TIME(0,30,0), "h:mm AM/PM") & " - " & TEXT(TIMEVALUE(MID(A7,FIND("- ",A7)+2,99))+TIME(0,30,0), "h:mm AM/PM") -> 3:30 AM - 4:00 AM | B8: =IF(COUNTA('Jenny Li'!B8,'Huiyu Yie'!B8,'Eddie Nguyen'!B8,'Johnny Lin'!B8,'Ashley Hui'!B8)=0,0,COUNTA('Jenny Li'!B8,'Huiyu Yie'!B8,'Eddie Nguyen'!B8,'Johnny Lin'!B8,'Ashley Hui'!B8)) -> 5 | C8: =IF(COUNTA('Jenny Li'!C8,'Huiyu Yie'!C8,'Eddie Nguyen'!C8,'Johnny Lin'!C8,'Ashley Hui'!C8)=0,0,COUNTA('Jenny Li'!C8,'Huiyu Yie'!C8,'Eddie Nguyen'!C8,'Johnny Lin'!C8,'Ashley Hui'!C8)) -> 5 | D8: =IF(COUNTA('Jenny Li'!D8,'Huiyu Yie'!D8,'Eddie Nguyen'!D8,'Johnny Lin'!D8,'Ashley Hui'!D8)=0,0,COUNTA('Jenny Li'!D8,'Huiyu Yie'!D8,'Eddie Nguyen'!D8,'Johnny Lin'!D8,'Ashley Hui'!D8)) -> 5 | E8: =IF(COUNTA('Jenny Li'!E8,'Huiyu Yie'!E8,'Eddie Nguyen'!E8,'Johnny Lin'!E8,'Ashley Hui'!E8)=0,0,COUNTA('Jenny Li'!E8,'Huiyu Yie'!E8,'Eddie Nguyen'!E8,'Johnny Lin'!E8,'Ashley Hui'!E8)) -> 5 | F8: =IF(COUNTA('Jenny Li'!F8,'Huiyu Yie'!F8,'Eddie Nguyen'!F8,'Johnny Lin'!F8,'Ashley Hui'!F8)=0,0,COUNTA('Jenny Li'!F8,'Huiyu Yie'!F8,'Eddie Nguyen'!F8,'Johnny Lin'!F8,'Ashley Hui'!F8)) -> 5 | G8: =IF(COUNTA('Jenny Li'!G8,'Huiyu Yie'!G8,'Eddie Nguyen'!G8,'Johnny Lin'!G8,'Ashley Hui'!G8)=0,0,COUNTA('Jenny Li'!G8,'Huiyu Yie'!G8,'Eddie Nguyen'!G8,'Johnny Lin'!G8,'Ashley Hui'!G8)) -> 4 | H8: =IF(COUNTA('Jenny Li'!H8,'Huiyu Yie'!H8,'Eddie Nguyen'!H8,'Johnny Lin'!H8,'Ashley Hui'!H8)=0,0,COUNTA('Jenny Li'!H8,'Huiyu Yie'!H8,'Eddie Nguyen'!H8,'Johnny Lin'!H8,'Ashley Hui'!H8)) -> 4
A9: =TEXT(TIMEVALUE(LEFT(A8,FIND(" -",A8)-1))+TIME(0,30,0), "h:mm AM/PM") & " - " & TEXT(TIMEVALUE(MID(A8,FIND("- ",A8)+2,99))+TIME(0,30,0), "h:mm AM/PM") -> 4:00 AM - 4:30 AM | B9: =IF(COUNTA('Jenny Li'!B9,'Huiyu Yie'!B9,'Eddie Nguyen'!B9,'Johnny Lin'!B9,'Ashley Hui'!B9)=0,0,COUNTA('Jenny Li'!B9,'Huiyu Yie'!B9,'Eddie Nguyen'!B9,'Johnny Lin'!B9,'Ashley Hui'!B9)) -> 5 | C9: =IF(COUNTA('Jenny Li'!C9,'Huiyu Yie'!C9,'Eddie Nguyen'!C9,'Johnny Lin'!C9,'Ashley Hui'!C9)=0,0,COUNTA('Jenny Li'!C9,'Huiyu Yie'!C9,'Eddie Nguyen'!C9,'Johnny Lin'!C9,'Ashley Hui'!C9)) -> 5 | D9: =IF(COUNTA('Jenny Li'!D9,'Huiyu Yie'!D9,'Eddie Nguyen'!D9,'Johnny Lin'!D9,'Ashley Hui'!D9)=0,0,COUNTA('Jenny Li'!D9,'Huiyu Yie'!D9,'Eddie Nguyen'!D9,'Johnny Lin'!D9,'Ashley Hui'!D9)) -> 5 | E9: =IF(COUNTA('Jenny Li'!E9,'Huiyu Yie'!E9,'Eddie Nguyen'!E9,'Johnny Lin'!E9,'Ashley Hui'!E9)=0,0,COUNTA('Jenny Li'!E9,'Huiyu Yie'!E9,'Eddie Nguyen'!E9,'Johnny Lin'!E9,'Ashley Hui'!E9)) -> 5 | F9: =IF(COUNTA('Jenny Li'!F9,'Huiyu Yie'!F9,'Eddie Nguyen'!F9,'Johnny Lin'!F9,'Ashley Hui'!F9)=0,0,COUNTA('Jenny Li'!F9,'Huiyu Yie'!F9,'Eddie Nguyen'!F9,'Johnny Lin'!F9,'Ashley Hui'!F9)) -> 5 | G9: =IF(COUNTA('Jenny Li'!G9,'Huiyu Yie'!G9,'Eddie Nguyen'!G9,'Johnny Lin'!G9,'Ashley Hui'!G9)=0,0,COUNTA('Jenny Li'!G9,'Huiyu Yie'!G9,'Eddie Nguyen'!G9,'Johnny Lin'!G9,'Ashley Hui'!G9)) -> 4 | H9: =IF(COUNTA('Jenny Li'!H9,'Huiyu Yie'!H9,'Eddie Nguyen'!H9,'Johnny Lin'!H9,'Ashley Hui'!H9)=0,0,COUNTA('Jenny Li'!H9,'Huiyu Yie'!H9,'Eddie Nguyen'!H9,'Johnny Lin'!H9,'Ashley Hui'!H9)) -> 4
A10: =TEXT(TIMEVALUE(LEFT(A9,FIND(" -",A9)-1))+TIME(0,30,0), "h:mm AM/PM") & " - " & TEXT(TIMEVALUE(MID(A9,FIND("- ",A9)+2,99))+TIME(0,30,0), "h:mm AM/PM") -> 4:30 AM - 5:00 AM | B10: =IF(COUNTA('Jenny Li'!B10,'Huiyu Yie'!B10,'Eddie Nguyen'!B10,'Johnny Lin'!B10,'Ashley Hui'!B10)=0,0,COUNTA('Jenny Li'!B10,'Huiyu Yie'!B10,'Eddie Nguyen'!B10,'Johnny Lin'!B10,'Ashley Hui'!B10)) -> 5 | C10: =IF(COUNTA('Jenny Li'!C10,'Huiyu Yie'!C10,'Eddie Nguyen'!C10,'Johnny Lin'!C10,'Ashley Hui'!C10)=0,0,COUNTA('Jenny Li'!C10,'Huiyu Yie'!C10,'Eddie Nguyen'!C10,'Johnny Lin'!C10,'Ashley Hui'!C10)) -> 5 | D10: =IF(COUNTA('Jenny Li'!D10,'Huiyu Yie'!D10,'Eddie Nguyen'!D10,'Johnny Lin'!D10,'Ashley Hui'!D10)=0,0,COUNTA('Jenny Li'!D10,'Huiyu Yie'!D10,'Eddie Nguyen'!D10,'Johnny Lin'!D10,'Ashley Hui'!D10)) -> 5 | E10: =IF(COUNTA('Jenny Li'!E10,'Huiyu Yie'!E10,'Eddie Nguyen'!E10,'Johnny Lin'!E10,'Ashley Hui'!E10)=0,0,COUNTA('Jenny Li'!E10,'Huiyu Yie'!E10,'Eddie Nguyen'!E10,'Johnny Lin'!E10,'Ashley Hui'!E10)) -> 5 | F10: =IF(COUNTA('Jenny Li'!F10,'Huiyu Yie'!F10,'Eddie Nguyen'!F10,'Johnny Lin'!F10,'Ashley Hui'!F10)=0,0,COUNTA('Jenny Li'!F10,'Huiyu Yie'!F10,'Eddie Nguyen'!F10,'Johnny Lin'!F10,'Ashley Hui'!F10)) -> 5 | G10: =IF(COUNTA('Jenny Li'!G10,'Huiyu Yie'!G10,'Eddie Nguyen'!G10,'Johnny Lin'!G10,'Ashley Hui'!G10)=0,0,COUNTA('Jenny Li'!G10,'Huiyu Yie'!G10,'Eddie Nguyen'!G10,'Johnny Lin'!G10,'Ashley Hui'!G10)) -> 4 | H10: =IF(COUNTA('Jenny Li'!H10,'Huiyu Yie'!H10,'Eddie Nguyen'!H10,'Johnny Lin'!H10,'Ashley Hui'!H10)=0,0,COUNTA('Jenny Li'!H10,'Huiyu Yie'!H10,'Eddie Nguyen'!H10,'Johnny Lin'!H10,'Ashley Hui'!H10)) -> 4
A11: =TEXT(TIMEVALUE(LEFT(A10,FIND(" -",A10)-1))+TIME(0,30,0), "h:mm AM/PM") & " - " & TEXT(TIMEVALUE(MID(A10,FIND("- ",A10)+2,99))+TIME(0,30,0), "h:mm AM/PM") -> 5:00 AM - 5:30 AM | B11: =IF(COUNTA('Jenny Li'!B11,'Huiyu Yie'!B11,'Eddie Nguyen'!B11,'Johnny Lin'!B11,'Ashley Hui'!B11)=0,0,COUNTA('Jenny Li'!B11,'Huiyu Yie'!B11,'Eddie Nguyen'!B11,'Johnny Lin'!B11,'Ashley Hui'!B11)) -> 5 | C11: =IF(COUNTA('Jenny Li'!C11,'Huiyu Yie'!C11,'Eddie Nguyen'!C11,'Johnny Lin'!C11,'Ashley Hui'!C11)=0,0,COUNTA('Jenny Li'!C11,'Huiyu Yie'!C11,'Eddie Nguyen'!C11,'Johnny Lin'!C11,'Ashley Hui'!C11)) -> 5 | D11: =IF(COUNTA('Jenny Li'!D11,'Huiyu Yie'!D11,'Eddie Nguyen'!D11,'Johnny Lin'!D11,'Ashley Hui'!D11)=0,0,COUNTA('Jenny Li'!D11,'Huiyu Yie'!D11,'Eddie Nguyen'!D11,'Johnny Lin'!D11,'Ashley Hui'!D11)) -> 5 | E11: =IF(COUNTA('Jenny Li'!E11,'Huiyu Yie'!E11,'Eddie Nguyen'!E11,'Johnny Lin'!E11,'Ashley Hui'!E11)=0,0,COUNTA('Jenny Li'!E11,'Huiyu Yie'!E11,'Eddie Nguyen'!E11,'Johnny Lin'!E11,'Ashley Hui'!E11)) -> 5 | F11: =IF(COUNTA('Jenny Li'!F11,'Huiyu Yie'!F11,'Eddie Nguyen'!F11,'Johnny Lin'!F11,'Ashley Hui'!F11)=0,0,COUNTA('Jenny Li'!F11,'Huiyu Yie'!F11,'Eddie Nguyen'!F11,'Johnny Lin'!F11,'Ashley Hui'!F11)) -> 5 | G11: =IF(COUNTA('Jenny Li'!G11,'Huiyu Yie'!G11,'Eddie Nguyen'!G11,'Johnny Lin'!G11,'Ashley Hui'!G11)=0,0,COUNTA('Jenny Li'!G11,'Huiyu Yie'!G11,'Eddie Nguyen'!G11,'Johnny Lin'!G11,'Ashley Hui'!G11)) -> 4 | H11: =IF(COUNTA('Jenny Li'!H11,'Huiyu Yie'!H11,'Eddie Nguyen'!H11,'Johnny Lin'!H11,'Ashley Hui'!H11)=0,0,COUNTA('Jenny Li'!H11,'Huiyu Yie'!H11,'Eddie Nguyen'!H11,'Johnny Lin'!H11,'Ashley Hui'!H11)) -> 4
A12: =TEXT(TIMEVALUE(LEFT(A11,FIND(" -",A11)-1))+TIME(0,30,0), "h:mm AM/PM") & " - " & TEXT(TIMEVALUE(MID(A11,FIND("- ",A11)+2,99))+TIME(0,30,0), "h:mm AM/PM") -> 5:30 AM - 6:00 AM | B12: =IF(COUNTA('Jenny Li'!B12,'Huiyu Yie'!B12,'Eddie Nguyen'!B12,'Johnny Lin'!B12,'Ashley Hui'!B12)=0,0,COUNTA('Jenny Li'!B12,'Huiyu Yie'!B12,'Eddie Nguyen'!B12,'Johnny Lin'!B12,'Ashley Hui'!B12)) -> 5 | C12: =IF(COUNTA('Jenny Li'!C12,'Huiyu Yie'!C12,'Eddie Nguyen'!C12,'Johnny Lin'!C12,'Ashley Hui'!C12)=0,0,COUNTA('Jenny Li'!C12,'Huiyu Yie'!C12,'Eddie Nguyen'!C12,'Johnny Lin'!C12,'Ashley Hui'!C12)) -> 5 | D12: =IF(COUNTA('Jenny Li'!D12,'Huiyu Yie'!D12,'Eddie Nguyen'!D12,'Johnny Lin'!D12,'Ashley Hui'!D12)=0,0,COUNTA('Jenny Li'!D12,'Huiyu Yie'!D12,'Eddie Nguyen'!D12,'Johnny Lin'!D12,'Ashley Hui'!D12)) -> 5 | E12: =IF(COUNTA('Jenny Li'!E12,'Huiyu Yie'!E12,'Eddie Nguyen'!E12,'Johnny Lin'!E12,'Ashley Hui'!E12)=0,0,COUNTA('Jenny Li'!E12,'Huiyu Yie'!E12,'Eddie Nguyen'!E12,'Johnny Lin'!E12,'Ashley Hui'!E12)) -> 5 | F12: =IF(COUNTA('Jenny Li'!F12,'Huiyu Yie'!F12,'Eddie Nguyen'!F12,'Johnny Lin'!F12,'Ashley Hui'!F12)=0,0,COUNTA('Jenny Li'!F12,'Huiyu Yie'!F12,'Eddie Nguyen'!F12,'Johnny Lin'!F12,'Ashley Hui'!F12)) -> 5 | G12: =IF(COUNTA('Jenny Li'!G12,'Huiyu Yie'!G12,'Eddie Nguyen'!G12,'Johnny Lin'!G12,'Ashley Hui'!G12)=0,0,COUNTA('Jenny Li'!G12,'Huiyu Yie'!G12,'Eddie Nguyen'!G12,'Johnny Lin'!G12,'Ashley Hui'!G12)) -> 4 | H12: =IF(COUNTA('Jenny Li'!H12,'Huiyu Yie'!H12,'Eddie Nguyen'!H12,'Johnny Lin'!H12,'Ashley Hui'!H12)=0,0,COUNTA('Jenny Li'!H12,'Huiyu Yie'!H12,'Eddie Nguyen'!H12,'Johnny Lin'!H12,'Ashley Hui'!H12)) -> 4
A13: =TEXT(TIMEVALUE(LEFT(A12,FIND(" -",A12)-1))+TIME(0,30,0), "h:mm AM/PM") & " - " & TEXT(TIMEVALUE(MID(A12,FIND("- ",A12)+2,99))+TIME(0,30,0), "h:mm AM/PM") -> 6:00 AM - 6:30 AM | B13: =IF(COUNTA('Jenny Li'!B13,'Huiyu Yie'!B13,'Eddie Nguyen'!B13,'Johnny Lin'!B13,'Ashley Hui'!B13)=0,0,COUNTA('Jenny Li'!B13,'Huiyu Yie'!B13,'Eddie Nguyen'!B13,'Johnny Lin'!B13,'Ashley Hui'!B13)) -> 5 | C13: =IF(COUNTA('Jenny Li'!C13,'Huiyu Yie'!C13,'Eddie Nguyen'!C13,'Johnny Lin'!C13,'Ashley Hui'!C13)=0,0,COUNTA('Jenny Li'!C13,'Huiyu Yie'!C13,'Eddie Nguyen'!C13,'Johnny Lin'!C13,'Ashley Hui'!C13)) -> 5 | D13: =IF(COUNTA('Jenny Li'!D13,'Huiyu Yie'!D13,'Eddie Nguyen'!D13,'Johnny Lin'!D13,'Ashley Hui'!D13)=0,0,COUNTA('Jenny Li'!D13,'Huiyu Yie'!D13,'Eddie Nguyen'!D13,'Johnny Lin'!D13,'Ashley Hui'!D13)) -> 5 | E13: =IF(COUNTA('Jenny Li'!E13,'Huiyu Yie'!E13,'Eddie Nguyen'!E13,'Johnny Lin'!E13,'Ashley Hui'!E13)=0,0,COUNTA('Jenny Li'!E13,'Huiyu Yie'!E13,'Eddie Nguyen'!E13,'Johnny Lin'!E13,'Ashley Hui'!E13)) -> 5 | F13: =IF(COUNTA('Jenny Li'!F13,'Huiyu Yie'!F13,'Eddie Nguyen'!F13,'Johnny Lin'!F13,'Ashley Hui'!F13)=0,0,COUNTA('Jenny Li'!F13,'Huiyu Yie'!F13,'Eddie Nguyen'!F13,'Johnny Lin'!F13,'Ashley Hui'!F13)) -> 5 | G13: =IF(COUNTA('Jenny Li'!G13,'Huiyu Yie'!G13,'Eddie Nguyen'!G13,'Johnny Lin'!G13,'Ashley Hui'!G13)=0,0,COUNTA('Jenny Li'!G13,'Huiyu Yie'!G13,'Eddie Nguyen'!G13,'Johnny Lin'!G13,'Ashley Hui'!G13)) -> 4 | H13: =IF(COUNTA('Jenny Li'!H13,'Huiyu Yie'!H13,'Eddie Nguyen'!H13,'Johnny Lin'!H13,'Ashley Hui'!H13)=0,0,COUNTA('Jenny Li'!H13,'Huiyu Yie'!H13,'Eddie Nguyen'!H13,'Johnny Lin'!H13,'Ashley Hui'!H13)) -> 4
A14: =TEXT(TIMEVALUE(LEFT(A13,FIND(" -",A13)-1))+TIME(0,30,0), "h:mm AM/PM") & " - " & TEXT(TIMEVALUE(MID(A13,FIND("- ",A13)+2,99))+TIME(0,30,0), "h:mm AM/PM") -> 6:30 AM - 7:00 AM | B14: =IF(COUNTA('Jenny Li'!B14,'Huiyu Yie'!B14,'Eddie Nguyen'!B14,'Johnny Lin'!B14,'Ashley Hui'!B14)=0,0,COUNTA('Jenny Li'!B14,'Huiyu Yie'!B14,'Eddie Nguyen'!B14,'Johnny Lin'!B14,'Ashley Hui'!B14)) -> 5 | C14: =IF(COUNTA('Jenny Li'!C14,'Huiyu Yie'!C14,'Eddie Nguyen'!C14,'Johnny Lin'!C14,'Ashley Hui'!C14)=0,0,COUNTA('Jenny Li'!C14,'Huiyu Yie'!C14,'Eddie Nguyen'!C14,'Johnny Lin'!C14,'Ashley Hui'!C14)) -> 5 | D14: =IF(COUNTA('Jenny Li'!D14,'Huiyu Yie'!D14,'Eddie Nguyen'!D14,'Johnny Lin'!D14,'Ashley Hui'!D14)=0,0,COUNTA('Jenny Li'!D14,'Huiyu Yie'!D14,'Eddie Nguyen'!D14,'Johnny Lin'!D14,'Ashley Hui'!D14)) -> 5 | E14: =IF(COUNTA('Jenny Li'!E14,'Huiyu Yie'!E14,'Eddie Nguyen'!E14,'Johnny Lin'!E14,'Ashley Hui'!E14)=0,0,COUNTA('Jenny Li'!E14,'Huiyu Yie'!E14,'Eddie Nguyen'!E14,'Johnny Lin'!E14,'Ashley Hui'!E14)) -> 5 | F14: =IF(COUNTA('Jenny Li'!F14,'Huiyu Yie'!F14,'Eddie Nguyen'!F14,'Johnny Lin'!F14,'Ashley Hui'!F14)=0,0,COUNTA('Jenny Li'!F14,'Huiyu Yie'!F14,'Eddie Nguyen'!F14,'Johnny Lin'!F14,'Ashley Hui'!F14)) -> 5 | G14: =IF(COUNTA('Jenny Li'!G14,'Huiyu Yie'!G14,'Eddie Nguyen'!G14,'Johnny Lin'!G14,'Ashley Hui'!G14)=0,0,COUNTA('Jenny Li'!G14,'Huiyu Yie'!G14,'Eddie Nguyen'!G14,'Johnny Lin'!G14,'Ashley Hui'!G14)) -> 4 | H14: =IF(COUNTA('Jenny Li'!H14,'Huiyu Yie'!H14,'Eddie Nguyen'!H14,'Johnny Lin'!H14,'Ashley Hui'!H14)=0,0,COUNTA('Jenny Li'!H14,'Huiyu Yie'!H14,'Eddie Nguyen'!H14,'Johnny Lin'!H14,'Ashley Hui'!H14)) -> 4
A15: =TEXT(TIMEVALUE(LEFT(A14,FIND(" -",A14)-1))+TIME(0,30,0), "h:mm AM/PM") & " - " & TEXT(TIMEVALUE(MID(A14,FIND("- ",A14)+2,99))+TIME(0,30,0), "h:mm AM/PM") -> 7:00 AM - 7:30 AM | B15: =IF(COUNTA('Jenny Li'!B15,'Huiyu Yie'!B15,'Eddie Nguyen'!B15,'Johnny Lin'!B15,'Ashley Hui'!B15)=0,0,COUNTA('Jenny Li'!B15,'Huiyu Yie'!B15,'Eddie Nguyen'!B15,'Johnny Lin'!B15,'Ashley Hui'!B15)) -> 5 | C15: =IF(COUNTA('Jenny Li'!C15,'Huiyu Yie'!C15,'Eddie Nguyen'!C15,'Johnny Lin'!C15,'Ashley Hui'!C15)=0,0,COUNTA('Jenny Li'!C15,'Huiyu Yie'!C15,'Eddie Nguyen'!C15,'Johnny Lin'!C15,'Ashley Hui'!C15)) -> 5 | D15: =IF(COUNTA('Jenny Li'!D15,'Huiyu Yie'!D15,'Eddie Nguyen'!D15,'Johnny Lin'!D15,'Ashley Hui'!D15)=0,0,COUNTA('Jenny Li'!D15,'Huiyu Yie'!D15,'Eddie Nguyen'!D15,'Johnny Lin'!D15,'Ashley Hui'!D15)) -> 5 | E15: =IF(COUNTA('Jenny Li'!E15,'Huiyu Yie'!E15,'Eddie Nguyen'!E15,'Johnny Lin'!E15,'Ashley Hui'!E15)=0,0,COUNTA('Jenny Li'!E15,'Huiyu Yie'!E15,'Eddie Nguyen'!E15,'Johnny Lin'!E15,'Ashley Hui'!E15)) -> 5 | F15: =IF(COUNTA('Jenny Li'!F15,'Huiyu Yie'!F15,'Eddie Nguyen'!F15,'Johnny Lin'!F15,'Ashley Hui'!F15)=0,0,COUNTA('Jenny Li'!F15,'Huiyu Yie'!F15,'Eddie Nguyen'!F15,'Johnny Lin'!F15,'Ashley Hui'!F15)) -> 5 | G15: =IF(COUNTA('Jenny Li'!G15,'Huiyu Yie'!G15,'Eddie Nguyen'!G15,'Johnny Lin'!G15,'Ashley Hui'!G15)=0,0,COUNTA('Jenny Li'!G15,'Huiyu Yie'!G15,'Eddie Nguyen'!G15,'Johnny Lin'!G15,'Ashley Hui'!G15)) -> 4 | H15: =IF(COUNTA('Jenny Li'!H15,'Huiyu Yie'!H15,'Eddie Nguyen'!H15,'Johnny Lin'!H15,'Ashley Hui'!H15)=0,0,COUNTA('Jenny Li'!H15,'Huiyu Yie'!H15,'Eddie Nguyen'!H15,'Johnny Lin'!H15,'Ashley Hui'!H15)) -> 4
A16: =TEXT(TIMEVALUE(LEFT(A15,FIND(" -",A15)-1))+TIME(0,30,0), "h:mm AM/PM") & " - " & TEXT(TIMEVALUE(MID(A15,FIND("- ",A15)+2,99))+TIME(0,30,0), "h:mm AM/PM") -> 7:30 AM - 8:00 AM | B16: =IF(COUNTA('Jenny Li'!B16,'Huiyu Yie'!B16,'Eddie Nguyen'!B16,'Johnny Lin'!B16,'Ashley Hui'!B16)=0,0,COUNTA('Jenny Li'!B16,'Huiyu Yie'!B16,'Eddie Nguyen'!B16,'Johnny Lin'!B16,'Ashley Hui'!B16)) -> 5 | C16: =IF(COUNTA('Jenny Li'!C16,'Huiyu Yie'!C16,'Eddie Nguyen'!C16,'Johnny Lin'!C16,'Ashley Hui'!C16)=0,0,COUNTA('Jenny Li'!C16,'Huiyu Yie'!C16,'Eddie Nguyen'!C16,'Johnny Lin'!C16,'Ashley Hui'!C16)) -> 5 | D16: =IF(COUNTA('Jenny Li'!D16,'Huiyu Yie'!D16,'Eddie Nguyen'!D16,'Johnny Lin'!D16,'Ashley Hui'!D16)=0,0,COUNTA('Jenny Li'!D16,'Huiyu Yie'!D16,'Eddie Nguyen'!D16,'Johnny Lin'!D16,'Ashley Hui'!D16)) -> 5 | E16: =IF(COUNTA('Jenny Li'!E16,'Huiyu Yie'!E16,'Eddie Nguyen'!E16,'Johnny Lin'!E16,'Ashley Hui'!E16)=0,0,COUNTA('Jenny Li'!E16,'Huiyu Yie'!E16,'Eddie Nguyen'!E16,'Johnny Lin'!E16,'Ashley Hui'!E16)) -> 5 | F16: =IF(COUNTA('Jenny Li'!F16,'Huiyu Yie'!F16,'Eddie Nguyen'!F16,'Johnny Lin'!F16,'Ashley Hui'!F16)=0,0,COUNTA('Jenny Li'!F16,'Huiyu Yie'!F16,'Eddie Nguyen'!F16,'Johnny Lin'!F16,'Ashley Hui'!F16)) -> 5 | G16: =IF(COUNTA('Jenny Li'!G16,'Huiyu Yie'!G16,'Eddie Nguyen'!G16,'Johnny Lin'!G16,'Ashley Hui'!G16)=0,0,COUNTA('Jenny Li'!G16,'Huiyu Yie'!G16,'Eddie Nguyen'!G16,'Johnny Lin'!G16,'Ashley Hui'!G16)) -> 4 | H16: =IF(COUNTA('Jenny Li'!H16,'Huiyu Yie'!H16,'Eddie Nguyen'!H16,'Johnny Lin'!H16,'Ashley Hui'!H16)=0,0,COUNTA('Jenny Li'!H16,'Huiyu Yie'!H16,'Eddie Nguyen'!H16,'Johnny Lin'!H16,'Ashley Hui'!H16)) -> 4
A17: =TEXT(TIMEVALUE(LEFT(A16,FIND(" -",A16)-1))+TIME(0,30,0), "h:mm AM/PM") & " - " & TEXT(TIMEVALUE(MID(A16,FIND("- ",A16)+2,99))+TIME(0,30,0), "h:mm AM/PM") -> 8:00 AM - 8:30 AM | B17: =IF(COUNTA('Jenny Li'!B17,'Huiyu Yie'!B17,'Eddie Nguyen'!B17,'Johnny Lin'!B17,'Ashley Hui'!B17)=0,0,COUNTA('Jenny Li'!B17,'Huiyu Yie'!B17,'Eddie Nguyen'!B17,'Johnny Lin'!B17,'Ashley Hui'!B17)) -> 5 | C17: =IF(COUNTA('Jenny Li'!C17,'Huiyu Yie'!C17,'Eddie Nguyen'!C17,'Johnny Lin'!C17,'Ashley Hui'!C17)=0,0,COUNTA('Jenny Li'!C17,'Huiyu Yie'!C17,'Eddie Nguyen'!C17,'Johnny Lin'!C17,'Ashley Hui'!C17)) -> 5 | D17: =IF(COUNTA('Jenny Li'!D17,'Huiyu Yie'!D17,'Eddie Nguyen'!D17,'Johnny Lin'!D17,'Ashley Hui'!D17)=0,0,COUNTA('Jenny Li'!D17,'Huiyu Yie'!D17,'Eddie Nguyen'!D17,'Johnny Lin'!D17,'Ashley Hui'!D17)) -> 5 | E17: =IF(COUNTA('Jenny Li'!E17,'Huiyu Yie'!E17,'Eddie Nguyen'!E17,'Johnny Lin'!E17,'Ashley Hui'!E17)=0,0,COUNTA('Jenny Li'!E17,'Huiyu Yie'!E17,'Eddie Nguyen'!E17,'Johnny Lin'!E17,'Ashley Hui'!E17)) -> 5 | F17: =IF(COUNTA('Jenny Li'!F17,'Huiyu Yie'!F17,'Eddie Nguyen'!F17,'Johnny Lin'!F17,'Ashley Hui'!F17)=0,0,COUNTA('Jenny Li'!F17,'Huiyu Yie'!F17,'Eddie Nguyen'!F17,'Johnny Lin'!F17,'Ashley Hui'!F17)) -> 5 | G17: =IF(COUNTA('Jenny Li'!G17,'Huiyu Yie'!G17,'Eddie Nguyen'!G17,'Johnny Lin'!G17,'Ashley Hui'!G17)=0,0,COUNTA('Jenny Li'!G17,'Huiyu Yie'!G17,'Eddie Nguyen'!G17,'Johnny Lin'!G17,'Ashley Hui'!G17)) -> 4 | H17: =IF(COUNTA('Jenny Li'!H17,'Huiyu Yie'!H17,'Eddie Nguyen'!H17,'Johnny Lin'!H17,'Ashley Hui'!H17)=0,0,COUNTA('Jenny Li'!H17,'Huiyu Yie'!H17,'Eddie Nguyen'!H17,'Johnny Lin'!H17,'Ashley Hui'!H17)) -> 4
A18: =TEXT(TIMEVALUE(LEFT(A17,FIND(" -",A17)-1))+TIME(0,30,0), "h:mm AM/PM") & " - " & TEXT(TIMEVALUE(MID(A17,FIND("- ",A17)+2,99))+TIME(0,30,0), "h:mm AM/PM") -> 8:30 AM - 9:00 AM | B18: =IF(COUNTA('Jenny Li'!B18,'Huiyu Yie'!B18,'Eddie Nguyen'!B18,'Johnny Lin'!B18,'Ashley Hui'!B18)=0,0,COUNTA('Jenny Li'!B18,'Huiyu Yie'!B18,'Eddie Nguyen'!B18,'Johnny Lin'!B18,'Ashley Hui'!B18)) -> 5 | C18: =IF(COUNTA('Jenny Li'!C18,'Huiyu Yie'!C18,'Eddie Nguyen'!C18,'Johnny Lin'!C18,'Ashley Hui'!C18)=0,0,COUNTA('Jenny Li'!C18,'Huiyu Yie'!C18,'Eddie Nguyen'!C18,'Johnny Lin'!C18,'Ashley Hui'!C18)) -> 5 | D18: =IF(COUNTA('Jenny Li'!D18,'Huiyu Yie'!D18,'Eddie Nguyen'!D18,'Johnny Lin'!D18,'Ashley Hui'!D18)=0,0,COUNTA('Jenny Li'!D18,'Huiyu Yie'!D18,'Eddie Nguyen'!D18,'Johnny Lin'!D18,'Ashley Hui'!D18)) -> 5 | E18: =IF(COUNTA('Jenny Li'!E18,'Huiyu Yie'!E18,'Eddie Nguyen'!E18,'Johnny Lin'!E18,'Ashley Hui'!E18)=0,0,COUNTA('Jenny Li'!E18,'Huiyu Yie'!E18,'Eddie Nguyen'!E18,'Johnny Lin'!E18,'Ashley Hui'!E18)) -> 5 | F18: =IF(COUNTA('Jenny Li'!F18,'Huiyu Yie'!F18,'Eddie Nguyen'!F18,'Johnny Lin'!F18,'Ashley Hui'!F18)=0,0,COUNTA('Jenny Li'!F18,'Huiyu Yie'!F18,'Eddie Nguyen'!F18,'Johnny Lin'!F18,'Ashley Hui'!F18)) -> 5 | G18: =IF(COUNTA('Jenny Li'!G18,'Huiyu Yie'!G18,'Eddie Nguyen'!G18,'Johnny Lin'!G18,'Ashley Hui'!G18)=0,0,COUNTA('Jenny Li'!G18,'Huiyu Yie'!G18,'Eddie Nguyen'!G18,'Johnny Lin'!G18,'Ashley Hui'!G18)) -> 4 | H18: =IF(COUNTA('Jenny Li'!H18,'Huiyu Yie'!H18,'Eddie Nguyen'!H18,'Johnny Lin'!H18,'Ashley Hui'!H18)=0,0,COUNTA('Jenny Li'!H18,'Huiyu Yie'!H18,'Eddie Nguyen'!H18,'Johnny Lin'!H18,'Ashley Hui'!H18)) -> 4
A19: =TEXT(TIMEVALUE(LEFT(A18,FIND(" -",A18)-1))+TIME(0,30,0), "h:mm AM/PM") & " - " & TEXT(TIMEVALUE(MID(A18,FIND("- ",A18)+2,99))+TIME(0,30,0), "h:mm AM/PM") -> 9:00 AM - 9:30 AM | B19: =IF(COUNTA('Jenny Li'!B19,'Huiyu Yie'!B19,'Eddie Nguyen'!B19,'Johnny Lin'!B19,'Ashley Hui'!B19)=0,0,COUNTA('Jenny Li'!B19,'Huiyu Yie'!B19,'Eddie Nguyen'!B19,'Johnny Lin'!B19,'Ashley Hui'!B19)) -> 4 | C19: =IF(COUNTA('Jenny Li'!C19,'Huiyu Yie'!C19,'Eddie Nguyen'!C19,'Johnny Lin'!C19,'Ashley Hui'!C19)=0,0,COUNTA('Jenny Li'!C19,'Huiyu Yie'!C19,'Eddie Nguyen'!C19,'Johnny Lin'!C19,'Ashley Hui'!C19)) -> 4 | D19: =IF(COUNTA('Jenny Li'!D19,'Huiyu Yie'!D19,'Eddie Nguyen'!D19,'Johnny Lin'!D19,'Ashley Hui'!D19)=0,0,COUNTA('Jenny Li'!D19,'Huiyu Yie'!D19,'Eddie Nguyen'!D19,'Johnny Lin'!D19,'Ashley Hui'!D19)) -> 4 | E19: =IF(COUNTA('Jenny Li'!E19,'Huiyu Yie'!E19,'Eddie Nguyen'!E19,'Johnny Lin'!E19,'Ashley Hui'!E19)=0,0,COUNTA('Jenny Li'!E19,'Huiyu Yie'!E19,'Eddie Nguyen'!E19,'Johnny Lin'!E19,'Ashley Hui'!E19)) -> 4 | F19: =IF(COUNTA('Jenny Li'!F19,'Huiyu Yie'!F19,'Eddie Nguyen'!F19,'Johnny Lin'!F19,'Ashley Hui'!F19)=0,0,COUNTA('Jenny Li'!F19,'Huiyu Yie'!F19,'Eddie Nguyen'!F19,'Johnny Lin'!F19,'Ashley Hui'!F19)) -> 4 | G19: =IF(COUNTA('Jenny Li'!G19,'Huiyu Yie'!G19,'Eddie Nguyen'!G19,'Johnny Lin'!G19,'Ashley Hui'!G19)=0,0,COUNTA('Jenny Li'!G19,'Huiyu Yie'!G19,'Eddie Nguyen'!G19,'Johnny Lin'!G19,'Ashley Hui'!G19)) -> 2 | H19: =IF(COUNTA('Jenny Li'!H19,'Huiyu Yie'!H19,'Eddie Nguyen'!H19,'Johnny Lin'!H19,'Ashley Hui'!H19)=0,0,COUNTA('Jenny Li'!H19,'Huiyu Yie'!H19,'Eddie Nguyen'!H19,'Johnny Lin'!H19,'Ashley Hui'!H19)) -> 1
... A36: =TEXT(TIMEVALUE(LEFT(A35,FIND(" -",A35)-1))+TIME(0,30,0), "h:mm AM/PM") & " - " & TEXT(TIMEVALUE(MID(A35,FIND("- ",A35)+2,99))+TIME(0,30,0), "h:mm AM/PM") -> 5:30 PM - 6:00 PM | B36: =IF(COUNTA('Jenny Li'!B36,'Huiyu Yie'!B36,'Eddie Nguyen'!B36,'Johnny Lin'!B36,'Ashley Hui'!B36)=0,0,COUNTA('Jenny Li'!B36,'Huiyu Yie'!B36,'Eddie Nguyen'!B36,'Johnny Lin'!B36,'Ashley Hui'!B36)) -> 2 | C36: =IF(COUNTA('Jenny Li'!C36,'Huiyu Yie'!C36,'Eddie Nguyen'!C36,'Johnny Lin'!C36,'Ashley Hui'!C36)=0,0,COUNTA('Jenny Li'!C36,'Huiyu Yie'!C36,'Eddie Nguyen'!C36,'Johnny Lin'!C36,'Ashley Hui'!C36)) -> 3 | D36: =IF(COUNTA('Jenny Li'!D36,'Huiyu Yie'!D36,'Eddie Nguyen'!D36,'Johnny Lin'!D36,'Ashley Hui'!D36)=0,0,COUNTA('Jenny Li'!D36,'Huiyu Yie'!D36,'Eddie Nguyen'!D36,'Johnny Lin'!D36,'Ashley Hui'!D36)) -> 2 | E36: =IF(COUNTA('Jenny Li'!E36,'Huiyu Yie'!E36,'Eddie Nguyen'!E36,'Johnny Lin'!E36,'Ashley Hui'!E36)=0,0,COUNTA('Jenny Li'!E36,'Huiyu Yie'!E36,'Eddie Nguyen'!E36,'Johnny Lin'!E36,'Ashley Hui'!E36)) -> 3 | F36: =IF(COUNTA('Jenny Li'!F36,'Huiyu Yie'!F36,'Eddie Nguyen'!F36,'Johnny Lin'!F36,'Ashley Hui'!F36)=0,0,COUNTA('Jenny Li'!F36,'Huiyu Yie'!F36,'Eddie Nguyen'!F36,'Johnny Lin'!F36,'Ashley Hui'!F36)) -> 1 | G36: =IF(COUNTA('Jenny Li'!G36,'Huiyu Yie'!G36,'Eddie Nguyen'!G36,'Johnny Lin'!G36,'Ashley Hui'!G36)=0,0,COUNTA('Jenny Li'!G36,'Huiyu Yie'!G36,'Eddie Nguyen'!G36,'Johnny Lin'!G36,'Ashley Hui'!G36)) -> 0 | H36: =IF(COUNTA('Jenny Li'!H36,'Huiyu Yie'!H36,'Eddie Nguyen'!H36,'Johnny Lin'!H36,'Ashley Hui'!H36)=0,0,COUNTA('Jenny Li'!H36,'Huiyu Yie'!H36,'Eddie Nguyen'!H36,'Johnny Lin'!H36,'Ashley Hui'!H36)) -> 0
A37: =TEXT(TIMEVALUE(LEFT(A36,FIND(" -",A36)-1))+TIME(0,30,0), "h:mm AM/PM") & " - " & TEXT(TIMEVALUE(MID(A36,FIND("- ",A36)+2,99))+TIME(0,30,0), "h:mm AM/PM") -> 6:00 PM - 6:30 PM | B37: =IF(COUNTA('Jenny Li'!B37,'Huiyu Yie'!B37,'Eddie Nguyen'!B37,'Johnny Lin'!B37,'Ashley Hui'!B38)=0,0,COUNTA('Jenny Li'!B37,'Huiyu Yie'!B37,'Eddie Nguyen'!B37,'Johnny Lin'!B37,'Ashley Hui'!B38)) -> 2 | C37: =IF(COUNTA('Jenny Li'!C37,'Huiyu Yie'!C37,'Eddie Nguyen'!C37,'Johnny Lin'!C37,'Ashley Hui'!C37)=0,0,COUNTA('Jenny Li'!C37,'Huiyu Yie'!C37,'Eddie Nguyen'!C37,'Johnny Lin'!C37,'Ashley Hui'!C37)) -> 4 | D37: =IF(COUNTA('Jenny Li'!D37,'Huiyu Yie'!D37,'Eddie Nguyen'!D37,'Johnny Lin'!D37,'Ashley Hui'!D37)=0,0,COUNTA('Jenny Li'!D37,'Huiyu Yie'!D37,'Eddie Nguyen'!D37,'Johnny Lin'!D37,'Ashley Hui'!D37)) -> 2 | E37: =IF(COUNTA('Jenny Li'!E37,'Huiyu Yie'!E37,'Eddie Nguyen'!E37,'Johnny Lin'!E37,'Ashley Hui'!E37)=0,0,COUNTA('Jenny Li'!E37,'Huiyu Yie'!E37,'Eddie Nguyen'!E37,'Johnny Lin'!E37,'Ashley Hui'!E37)) -> 4 | F37: =IF(COUNTA('Jenny Li'!F37,'Huiyu Yie'!F37,'Eddie Nguyen'!F37,'Johnny Lin'!F37,'Ashley Hui'!F37)=0,0,COUNTA('Jenny Li'!F37,'Huiyu Yie'!F37,'Eddie Nguyen'!F37,'Johnny Lin'!F37,'Ashley Hui'!F37)) -> 2 | G37: =IF(COUNTA('Jenny Li'!G37,'Huiyu Yie'!G37,'Eddie Nguyen'!G37,'Johnny Lin'!G37,'Ashley Hui'!G37)=0,0,COUNTA('Jenny Li'!G37,'Huiyu Yie'!G37,'Eddie Nguyen'!G37,'Johnny Lin'!G37,'Ashley Hui'!G37)) -> 1 | H37: =IF(COUNTA('Jenny Li'!H37,'Huiyu Yie'!H37,'Eddie Nguyen'!H37,'Johnny Lin'!H37,'Ashley Hui'!H37)=0,0,COUNTA('Jenny Li'!H37,'Huiyu Yie'!H37,'Eddie Nguyen'!H37,'Johnny Lin'!H37,'Ashley Hui'!H37)) -> 1
